{"timestamp":1768858436755,"type":"book","data":{"type":"book","timestamp":1768858436755,"asset_id":"9031636498902109489531840330955202379047865759768140186724288939684833165378","market":"161587","bids":[[0.01,50],[0.05,43.75],[0.06,5421.51],[0.26,56.25],[0.27,25]],"asks":[]}}
{"timestamp":1768858436883,"type":"book","data":{"type":"book","timestamp":1768858436883,"asset_id":"43577718766112357875300730326646730119346466279136183595509365799679832624641","market":"161587","bids":[],"asks":[[0.99,50],[0.95,43.75],[0.94,5421.51],[0.74,56.25],[0.73,25]]}}
{"timestamp":1768858438638,"type":"book","data":{"type":"book","timestamp":1768858438638,"asset_id":"32000187069377430896265944353073875929784130362721284251736314375740995009132","market":"161587","bids":[[0.01,50],[0.02,30.51],[0.03,5.51]],"asks":[]}}
{"timestamp":1768858438772,"type":"book","data":{"type":"book","timestamp":1768858438772,"asset_id":"72300811647490128998831837378933981624665087909864960667694762257393293709099","market":"161587","bids":[],"asks":[[0.99,50],[0.98,30.51],[0.97,5.51]]}}
{"timestamp":1768858438900,"type":"book","data":{"type":"book","timestamp":1768858438900,"asset_id":"113025031494916309150086220666714068684066916056870600664866463237320949012683","market":"161587","bids":[[0.01,70],[0.03,5.51],[0.06,30.51],[0.07,25]],"asks":[]}}
{"timestamp":1768858439056,"type":"book","data":{"type":"book","timestamp":1768858439056,"asset_id":"106502645861422820101428418410740039040950178042688282565606126950746542596804","market":"161587","bids":[],"asks":[[0.99,70],[0.97,5.51],[0.94,30.51],[0.93,25]]}}
{"timestamp":1768858440773,"type":"book","data":{"type":"book","timestamp":1768858440773,"asset_id":"23982213020675018791507326977308149379200692959141537028293395142867568952427","market":"161587","bids":[[0.001,14.99],[0.01,50],[0.02,25],[0.031,3225],[0.05,5.51],[0.99,82.39]],"asks":[]}}
{"timestamp":1768858440904,"type":"book","data":{"type":"book","timestamp":1768858440904,"asset_id":"93658466248405584999260870388818827582402881579193486826612628010719686456341","market":"161587","bids":[],"asks":[[0.999,14.99],[0.99,50],[0.98,25],[0.969,3225],[0.95,5.51],[0.01,82.39]]}}
{"timestamp":1768858441924,"type":"book","data":{"type":"book","timestamp":1768858441924,"asset_id":"60854482386705306074271452945147814262686505626338572994501795906620218532455","market":"161587","bids":[],"asks":[[0.999,100009.13],[0.998,55000],[0.997,11.56],[0.992,155],[0.991,56055],[0.99,27055.21],[0.989,155],[0.98,1400],[0.979,14.47],[0.95,1300],[0.92,155],[0.903,100],[0.902,10600],[0.901,100],[0.9,3500],[0.899,5.93],[0.859,1359],[0.8,50],[0.73,50],[0.66,50],[0.53,100],[0.51,100],[0.503,200],[0.502,1500],[0.501,100],[0.25,60],[0.233,60],[0.232,571],[0.231,60],[0.23,60],[0.228,5.51],[0.217,18.66],[0.216,33.26],[0.01,900],[0.009,757.54],[0.008,50.4],[0.007,45.31],[0.006,40.24],[0.005,35.17],[0.004,30.12],[0.003,25.07],[0.002,20.04],[0.001,1155]]}}
{"timestamp":1768858442053,"type":"book","data":{"type":"book","timestamp":1768858442053,"asset_id":"109974464011407510311184872783466711205513981066359875513765218021885225826488","market":"161587","bids":[[0.001,100009.13],[0.002,55000],[0.003,11.56],[0.008,155],[0.009,56055],[0.01,27055.21],[0.011,155],[0.02,1400],[0.021,14.47],[0.05,1300],[0.08,155],[0.097,100],[0.098,10600],[0.099,100],[0.1,3500],[0.101,5.93],[0.141,1359],[0.2,50],[0.27,50],[0.34,50],[0.47,100],[0.49,100],[0.497,200],[0.498,1500],[0.499,100],[0.75,60],[0.767,60],[0.768,571],[0.769,60],[0.77,60],[0.772,5.51],[0.783,18.66],[0.784,33.26],[0.99,900],[0.991,757.54],[0.992,50.4],[0.993,45.31],[0.994,40.24],[0.995,35.17],[0.996,30.12],[0.997,25.07],[0.998,20.04],[0.999,1155]],"asks":[]}}
{"timestamp":1768858445120,"type":"book","data":{"type":"book","timestamp":1768858445120,"asset_id":"104561417469280438624857704713303730213235315036975837304809065111097458149113","market":"161587","bids":[],"asks":[[0.999,100009.13],[0.998,55000],[0.997,14.79],[0.992,155],[0.991,56055],[0.99,27000],[0.989,155],[0.988,7.28],[0.98,2100],[0.97,300],[0.969,8.35],[0.95,200],[0.92,255],[0.903,100],[0.902,10600],[0.901,100],[0.9,3650],[0.899,5.93],[0.86,50],[0.85,500],[0.849,662],[0.8,50],[0.73,50],[0.66,50],[0.53,100],[0.51,100],[0.503,200],[0.502,1500],[0.501,100],[0.5,650],[0.25,60],[0.233,60],[0.232,570],[0.231,60],[0.23,60],[0.213,26.33],[0.212,16.53],[0.211,25],[0.21,11.02],[0.01,2840],[0.009,644],[0.001,5]]}}
{"timestamp":1768858445262,"type":"book","data":{"type":"book","timestamp":1768858445262,"asset_id":"90508786464936430054960174057014699141737305916344517232838682389750156463791","market":"161587","bids":[[0.001,100009.13],[0.002,55000],[0.003,14.79],[0.008,155],[0.009,56055],[0.01,27000],[0.011,155],[0.012,7.28],[0.02,2100],[0.03,300],[0.031,8.35],[0.05,200],[0.08,255],[0.097,100],[0.098,10600],[0.099,100],[0.1,3650],[0.101,5.93],[0.14,50],[0.15,500],[0.151,662],[0.2,50],[0.27,50],[0.34,50],[0.47,100],[0.49,100],[0.497,200],[0.498,1500],[0.499,100],[0.5,650],[0.75,60],[0.767,60],[0.768,570],[0.769,60],[0.77,60],[0.787,26.33],[0.788,16.53],[0.789,25],[0.79,11.02],[0.99,2840],[0.991,644],[0.999,5]],"asks":[]}}
{"timestamp":1768858445396,"type":"book","data":{"type":"book","timestamp":1768858445396,"asset_id":"51640950844529073540440468921446646609840378218681177771835773486695222195363","market":"161587","bids":[],"asks":[[0.999,99999],[0.998,55000],[0.992,155],[0.991,56055],[0.99,27050],[0.989,155],[0.98,2100],[0.97,300],[0.95,200],[0.92,255],[0.903,100],[0.902,10600],[0.901,100],[0.9,3650],[0.86,50],[0.85,500],[0.849,662],[0.8,50],[0.73,50],[0.66,50],[0.53,100],[0.51,100],[0.503,200],[0.502,1500],[0.501,100],[0.5,650],[0.25,60],[0.233,60],[0.232,917],[0.231,60],[0.23,60],[0.229,47.68],[0.228,5.51],[0.01,2900],[0.009,704.54],[0.008,50.4],[0.007,45.31],[0.006,40.24],[0.005,35.17],[0.004,30.12],[0.003,25.07],[0.002,20.04],[0.001,1155]]}}
{"timestamp":1768858445531,"type":"book","data":{"type":"book","timestamp":1768858445531,"asset_id":"45580499855571815703798438949570518410899588907349508423148937057071386680821","market":"161587","bids":[[0.001,99999],[0.002,55000],[0.008,155],[0.009,56055],[0.01,27050],[0.011,155],[0.02,2100],[0.03,300],[0.05,200],[0.08,255],[0.097,100],[0.098,10600],[0.099,100],[0.1,3650],[0.14,50],[0.15,500],[0.151,662],[0.2,50],[0.27,50],[0.34,50],[0.47,100],[0.49,100],[0.497,200],[0.498,1500],[0.499,100],[0.5,650],[0.75,60],[0.767,60],[0.768,917],[0.769,60],[0.77,60],[0.771,47.68],[0.772,5.51],[0.99,2900],[0.991,704.54],[0.992,50.4],[0.993,45.31],[0.994,40.24],[0.995,35.17],[0.996,30.12],[0.997,25.07],[0.998,20.04],[0.999,1155]],"asks":[]}}
{"timestamp":1768858445669,"type":"book","data":{"type":"book","timestamp":1768858445669,"asset_id":"80955465573788561519287799238070819726068512211014816914447962346674298193040","market":"161587","bids":[[0.001,100009.13],[0.002,55000],[0.003,11.56],[0.008,155],[0.009,56055],[0.01,27005.21],[0.011,155],[0.02,1400],[0.021,14.47],[0.05,1300],[0.06,5.51],[0.08,155],[0.097,100],[0.098,10600],[0.099,100],[0.1,3650],[0.101,5.93],[0.14,50],[0.15,500],[0.151,662],[0.2,50],[0.27,50],[0.34,50],[0.47,100],[0.49,100],[0.497,200],[0.498,1500],[0.499,100],[0.5,650],[0.75,60],[0.767,60],[0.768,572],[0.769,60],[0.77,60],[0.772,41.57],[0.773,25],[0.99,12748.49],[0.991,704.54],[0.992,50.4],[0.993,45.31],[0.994,40.24],[0.995,35.17],[0.996,30.12],[0.997,25.07],[0.998,20.04],[0.999,2098.48]],"asks":[]}}
{"timestamp":1768858445811,"type":"book","data":{"type":"book","timestamp":1768858445811,"asset_id":"113421581696345614187888921984273009220039924345606711784540408098901651166996","market":"161587","bids":[],"asks":[[0.999,100009.13],[0.998,55000],[0.997,11.56],[0.992,155],[0.991,56055],[0.99,27005.21],[0.989,155],[0.98,1400],[0.979,14.47],[0.95,1300],[0.94,5.51],[0.92,155],[0.903,100],[0.902,10600],[0.901,100],[0.9,3650],[0.899,5.93],[0.86,50],[0.85,500],[0.849,662],[0.8,50],[0.73,50],[0.66,50],[0.53,100],[0.51,100],[0.503,200],[0.502,1500],[0.501,100],[0.5,650],[0.25,60],[0.233,60],[0.232,572],[0.231,60],[0.23,60],[0.228,41.57],[0.227,25],[0.01,12748.49],[0.009,704.54],[0.008,50.4],[0.007,45.31],[0.006,40.24],[0.005,35.17],[0.004,30.12],[0.003,25.07],[0.002,20.04],[0.001,2098.48]]}}
{"timestamp":1768858449504,"type":"book","data":{"type":"book","timestamp":1768858449504,"asset_id":"104561417469280438624857704713303730213235315036975837304809065111097458149113","market":"0x74359b1889c9b4f5a84c1cac8cfd2dd6f48731fedb44f7a7e803b9c8cd6de6d8","bids":[],"asks":[[0.999,100009.13],[0.998,55000],[0.997,14.79],[0.992,155],[0.991,56055],[0.99,27000],[0.989,155],[0.988,7.28],[0.98,2100],[0.97,300],[0.969,8.35],[0.95,200],[0.92,255],[0.903,100],[0.902,10600],[0.901,100],[0.9,3650],[0.899,5.93],[0.86,50],[0.85,500],[0.8,50],[0.73,50],[0.66,50],[0.53,100],[0.51,100],[0.503,200],[0.502,1500],[0.501,100],[0.5,400],[0.25,60],[0.233,60],[0.232,570],[0.231,60],[0.23,60],[0.213,26.33],[0.212,16.53],[0.211,25],[0.21,11.02],[0.01,2840],[0.009,644],[0.001,5]],"hash":"83dc7b84109ca84346ae882b1933a229c51f00df"}}
{"timestamp":1768858449505,"type":"book","data":{"type":"book","timestamp":1768858449505,"asset_id":"109974464011407510311184872783466711205513981066359875513765218021885225826488","market":"0xd832ad310ac0e7586c26de1784c8acb2d9e050ad9a264e2bea6db9c0dc0832ed","bids":[[0.001,100009.13],[0.002,55000],[0.003,11.56],[0.008,155],[0.009,56055],[0.01,27055.21],[0.011,155],[0.02,1400],[0.021,14.47],[0.05,1300],[0.08,155],[0.097,100],[0.098,10600],[0.099,100],[0.1,3550],[0.101,5.93],[0.141,600],[0.2,50],[0.27,50],[0.34,50],[0.47,100],[0.49,100],[0.497,200],[0.498,1500],[0.499,100],[0.5,400],[0.75,60],[0.767,60],[0.768,571],[0.769,60],[0.77,60],[0.783,18.66],[0.784,33.26],[0.785,5.51],[0.99,900],[0.991,757.54],[0.992,50.4],[0.993,45.31],[0.994,40.24],[0.995,35.17],[0.996,30.12],[0.997,25.07],[0.998,20.04],[0.999,1155]],"asks":[],"hash":"4410f2cc150fb5f49489f29a3d28069456ee9619"}}
{"timestamp":1768858449505,"type":"book","data":{"type":"book","timestamp":1768858449505,"asset_id":"23982213020675018791507326977308149379200692959141537028293395142867568952427","market":"0x0afef6598f68b1b2d47bca956116bbaa7d11f39d665f883aae5cc126c8e991c9","bids":[[0.001,49.68],[0.002,7.49],[0.01,50],[0.011,7.58],[0.02,25],[0.029,20.39],[0.032,6250],[0.05,5.51],[0.051,5.4],[0.061,13.12],[0.99,82.39]],"asks":[],"hash":"c5ac3dd824c4e88cb5929b547ab2ffd647b2f646"}}
{"timestamp":1768858449505,"type":"book","data":{"type":"book","timestamp":1768858449505,"asset_id":"72300811647490128998831837378933981624665087909864960667694762257393293709099","market":"0xa011589aac6ecc279df805b5b5af8f624f16044eca2fdc89f4f554df3ea82fe5","bids":[],"asks":[[0.99,50],[0.98,30.51],[0.97,5.51]],"hash":"7eb9efea241bbab968e1c1a175087a337efaa241"}}
{"timestamp":1768858449505,"type":"book","data":{"type":"book","timestamp":1768858449505,"asset_id":"106502645861422820101428418410740039040950178042688282565606126950746542596804","market":"0x19d9dc9b734a8270440da3511c0127c64e18e7c034656dba600c67e1f671eec8","bids":[],"asks":[[0.99,76.03],[0.98,13.02],[0.97,5.51],[0.94,3363.51],[0.93,9.7],[0.68,27.86],[0.67,37.5],[0.66,25]],"hash":"4b6ee7e7aeb69a3464f5b6f7d9757afe5cdb2f07"}}
{"timestamp":1768858449505,"type":"book","data":{"type":"book","timestamp":1768858449505,"asset_id":"45580499855571815703798438949570518410899588907349508423148937057071386680821","market":"0xbe7dc7ab76f592bc89d6c6c606e28d119cb90dd503bd543c61d79d8c2cb18d0d","bids":[[0.001,99999],[0.002,55000],[0.008,155],[0.009,56055],[0.01,27050],[0.011,155],[0.02,2100],[0.03,300],[0.05,200],[0.08,255],[0.097,100],[0.098,10600],[0.099,100],[0.1,3650],[0.14,50],[0.15,500],[0.2,50],[0.27,50],[0.34,50],[0.47,100],[0.49,100],[0.497,200],[0.498,1500],[0.499,100],[0.5,400],[0.75,60],[0.767,60],[0.768,917],[0.769,60],[0.77,60],[0.771,47.68],[0.772,5.51],[0.99,2900],[0.991,704.54],[0.992,50.4],[0.993,45.31],[0.994,40.24],[0.995,35.17],[0.996,30.12],[0.997,25.07],[0.998,20.04],[0.999,1155]],"asks":[],"hash":"cf4cf4c3bedb4e4a3c2317e364d5852e9cb96080"}}
{"timestamp":1768858449506,"type":"book","data":{"type":"book","timestamp":1768858449506,"asset_id":"113025031494916309150086220666714068684066916056870600664866463237320949012683","market":"0x19d9dc9b734a8270440da3511c0127c64e18e7c034656dba600c67e1f671eec8","bids":[[0.01,76.03],[0.02,13.02],[0.03,5.51],[0.06,3363.51],[0.07,9.7],[0.32,27.86],[0.33,37.5],[0.34,25]],"asks":[],"hash":"2707e36c848854f1a301cc4c0d469594db194e09"}}
{"timestamp":1768858449506,"type":"book","data":{"type":"book","timestamp":1768858449506,"asset_id":"51640950844529073540440468921446646609840378218681177771835773486695222195363","market":"0xbe7dc7ab76f592bc89d6c6c606e28d119cb90dd503bd543c61d79d8c2cb18d0d","bids":[],"asks":[[0.999,99999],[0.998,55000],[0.992,155],[0.991,56055],[0.99,27050],[0.989,155],[0.98,2100],[0.97,300],[0.95,200],[0.92,255],[0.903,100],[0.902,10600],[0.901,100],[0.9,3650],[0.86,50],[0.85,500],[0.8,50],[0.73,50],[0.66,50],[0.53,100],[0.51,100],[0.503,200],[0.502,1500],[0.501,100],[0.5,400],[0.25,60],[0.233,60],[0.232,917],[0.231,60],[0.23,60],[0.229,47.68],[0.228,5.51],[0.01,2900],[0.009,704.54],[0.008,50.4],[0.007,45.31],[0.006,40.24],[0.005,35.17],[0.004,30.12],[0.003,25.07],[0.002,20.04],[0.001,1155]],"hash":"f550349519564ca99d181579556748cbd865a63b"}}
{"timestamp":1768858449506,"type":"book","data":{"type":"book","timestamp":1768858449506,"asset_id":"113421581696345614187888921984273009220039924345606711784540408098901651166996","market":"0x8884313775cb4f37d3de3fa1e9afc797d9d0fb72cae523fbfa7853fab179d500","bids":[],"asks":[[0.999,100009.13],[0.998,55000],[0.997,11.56],[0.992,155],[0.991,56055],[0.99,27005.21],[0.989,155],[0.98,1400],[0.979,14.47],[0.95,1300],[0.94,5.51],[0.92,155],[0.903,100],[0.902,10600],[0.901,100],[0.9,3650],[0.899,5.93],[0.86,50],[0.85,500],[0.8,50],[0.73,50],[0.66,50],[0.53,100],[0.51,100],[0.503,200],[0.502,1500],[0.501,100],[0.5,400],[0.25,60],[0.233,60],[0.232,572],[0.231,60],[0.23,60],[0.228,41.57],[0.227,25],[0.01,12748.49],[0.009,704.54],[0.008,50.4],[0.007,45.31],[0.006,40.24],[0.005,35.17],[0.004,30.12],[0.003,25.07],[0.002,20.04],[0.001,2098.48]],"hash":"195b44ba358731a66c14061969072c9a55aa632a"}}
{"timestamp":1768858449507,"type":"book","data":{"type":"book","timestamp":1768858449507,"asset_id":"80955465573788561519287799238070819726068512211014816914447962346674298193040","market":"0x8884313775cb4f37d3de3fa1e9afc797d9d0fb72cae523fbfa7853fab179d500","bids":[[0.001,100009.13],[0.002,55000],[0.003,11.56],[0.008,155],[0.009,56055],[0.01,27005.21],[0.011,155],[0.02,1400],[0.021,14.47],[0.05,1300],[0.06,5.51],[0.08,155],[0.097,100],[0.098,10600],[0.099,100],[0.1,3650],[0.101,5.93],[0.14,50],[0.15,500],[0.2,50],[0.27,50],[0.34,50],[0.47,100],[0.49,100],[0.497,200],[0.498,1500],[0.499,100],[0.5,400],[0.75,60],[0.767,60],[0.768,572],[0.769,60],[0.77,60],[0.772,41.57],[0.773,25],[0.99,12748.49],[0.991,704.54],[0.992,50.4],[0.993,45.31],[0.994,40.24],[0.995,35.17],[0.996,30.12],[0.997,25.07],[0.998,20.04],[0.999,2098.48]],"asks":[],"hash":"870e43dea8fc30f8ba7e4ac7d04ef51aeab5791c"}}
{"timestamp":1768858449507,"type":"book","data":{"type":"book","timestamp":1768858449507,"asset_id":"102470506234631856714287226623345182033813197411154001523556742367360332249186","market":"0xd95cae1f78c63f65c14098d643ada7421731ec63e24fcb99628d9e5362e7ac61","bids":[[0.001,49.68],[0.002,7.49],[0.01,50],[0.011,11.29],[0.03,5.51],[0.031,5.33],[0.04,25],[0.06,5.51],[0.082,28.05],[0.083,25],[0.99,25.51]],"asks":[],"hash":"c2a8b62ecfab929f5d6b7b882e5aeecb1518d114"}}
{"timestamp":1768858449507,"type":"book","data":{"type":"book","timestamp":1768858449507,"asset_id":"43577718766112357875300730326646730119346466279136183595509365799679832624641","market":"0x676d078b81497e987ad19344ca4e3569f89b4e659f91a545f8e9690d6dfa4b39","bids":[],"asks":[[0.99,56.37],[0.98,11.26],[0.94,3375.36],[0.73,37.5],[0.72,37.5],[0.71,25]],"hash":"ccb417f002c0b5eb793f2051ac9296838279189f"}}
{"timestamp":1768858449507,"type":"book","data":{"type":"book","timestamp":1768858449507,"asset_id":"90508786464936430054960174057014699141737305916344517232838682389750156463791","market":"0x74359b1889c9b4f5a84c1cac8cfd2dd6f48731fedb44f7a7e803b9c8cd6de6d8","bids":[[0.001,100009.13],[0.002,55000],[0.003,14.79],[0.008,155],[0.009,56055],[0.01,27000],[0.011,155],[0.012,7.28],[0.02,2100],[0.03,300],[0.031,8.35],[0.05,200],[0.08,255],[0.097,100],[0.098,10600],[0.099,100],[0.1,3650],[0.101,5.93],[0.14,50],[0.15,500],[0.2,50],[0.27,50],[0.34,50],[0.47,100],[0.49,100],[0.497,200],[0.498,1500],[0.499,100],[0.5,400],[0.75,60],[0.767,60],[0.768,570],[0.769,60],[0.77,60],[0.787,26.33],[0.788,16.53],[0.789,25],[0.79,11.02],[0.99,2840],[0.991,644],[0.999,5]],"asks":[],"hash":"8335a46767948468a6faec4990d2fe55451539d8"}}
{"timestamp":1768858449507,"type":"book","data":{"type":"book","timestamp":1768858449507,"asset_id":"32000187069377430896265944353073875929784130362721284251736314375740995009132","market":"0xa011589aac6ecc279df805b5b5af8f624f16044eca2fdc89f4f554df3ea82fe5","bids":[[0.01,50],[0.02,30.51],[0.03,5.51]],"asks":[],"hash":"cfd7cb185d82c51142245713eac53133ab66667f"}}
{"timestamp":1768858449507,"type":"book","data":{"type":"book","timestamp":1768858449507,"asset_id":"9031636498902109489531840330955202379047865759768140186724288939684833165378","market":"0x676d078b81497e987ad19344ca4e3569f89b4e659f91a545f8e9690d6dfa4b39","bids":[[0.01,56.37],[0.02,11.26],[0.06,3375.36],[0.27,37.5],[0.28,37.5],[0.29,25]],"asks":[],"hash":"0a192a8e43180e6dd628d60135d904d949c2266b"}}
{"timestamp":1768858449507,"type":"book","data":{"type":"book","timestamp":1768858449507,"asset_id":"31795349211219422607185815612973220690717749068121740516256733008230250593184","market":"0xd95cae1f78c63f65c14098d643ada7421731ec63e24fcb99628d9e5362e7ac61","bids":[],"asks":[[0.999,49.68],[0.998,7.49],[0.99,50],[0.989,11.29],[0.97,5.51],[0.969,5.33],[0.96,25],[0.94,5.51],[0.918,28.05],[0.917,25],[0.01,25.51]],"hash":"19dd8f089259402cee11b10befcd8040bdd059c1"}}
{"timestamp":1768858449507,"type":"book","data":{"type":"book","timestamp":1768858449507,"asset_id":"60854482386705306074271452945147814262686505626338572994501795906620218532455","market":"0xd832ad310ac0e7586c26de1784c8acb2d9e050ad9a264e2bea6db9c0dc0832ed","bids":[],"asks":[[0.999,100009.13],[0.998,55000],[0.997,11.56],[0.992,155],[0.991,56055],[0.99,27055.21],[0.989,155],[0.98,1400],[0.979,14.47],[0.95,1300],[0.92,155],[0.903,100],[0.902,10600],[0.901,100],[0.9,3550],[0.899,5.93],[0.859,600],[0.8,50],[0.73,50],[0.66,50],[0.53,100],[0.51,100],[0.503,200],[0.502,1500],[0.501,100],[0.5,400],[0.25,60],[0.233,60],[0.232,571],[0.231,60],[0.23,60],[0.217,18.66],[0.216,33.26],[0.215,5.51],[0.01,900],[0.009,757.54],[0.008,50.4],[0.007,45.31],[0.006,40.24],[0.005,35.17],[0.004,30.12],[0.003,25.07],[0.002,20.04],[0.001,1155]],"hash":"8634887878d52237a774e7a19d4b7d361c8876d6"}}
{"timestamp":1768858449507,"type":"book","data":{"type":"book","timestamp":1768858449507,"asset_id":"93658466248405584999260870388818827582402881579193486826612628010719686456341","market":"0x0afef6598f68b1b2d47bca956116bbaa7d11f39d665f883aae5cc126c8e991c9","bids":[],"asks":[[0.999,49.68],[0.998,7.49],[0.99,50],[0.989,7.58],[0.98,25],[0.971,20.39],[0.968,6250],[0.95,5.51],[0.949,5.4],[0.939,13.12],[0.01,82.39]],"hash":"fe7ecbf18af0945b4fa41dd0cf505da8b4d6550c"}}
{"timestamp":1768861060985,"type":"book","data":{"type":"book","timestamp":1768861060985,"asset_id":"9031636498902109489531840330955202379047865759768140186724288939684833165378","market":"0x676d078b81497e987ad19344ca4e3569f89b4e659f91a545f8e9690d6dfa4b39","bids":[[0.01,50],[0.02,700],[0.06,1696.51],[0.17,1176],[0.6,13.19],[0.62,51.46],[0.63,35.34],[0.64,5.51]],"asks":[],"hash":"7b120876165bac8ba534b734fffbe1a04e2b24f4"}}
{"timestamp":1768861060987,"type":"book","data":{"type":"book","timestamp":1768861060987,"asset_id":"83762004711915891788797964319803421904923212191800334283779459846638388049876","market":"0xa8e21d98ce3635fdafa916aa404f8dfd4eb941ec5a36e54b07f9fef1dcfa9051","bids":[],"asks":[[0.999,14.99],[0.99,50],[0.989,9090],[0.988,16666],[0.948,25],[0.947,5.51],[0.892,24.37],[0.891,25],[0.89,5.51]],"hash":"b51969e355af786d64a8f6e07c2608a5e80bebac"}}
{"timestamp":1768861060988,"type":"book","data":{"type":"book","timestamp":1768861060988,"asset_id":"105946555319717952586004333254949548955829524636247831439729957976174835757796","market":"0x29067ebc925c8bb2d14f0bb8c7946005e51538109dc2e4d201639a40232bc93c","bids":[[0.01,50],[0.02,25],[0.03,5.51]],"asks":[],"hash":"0de2ce2270694551c2f65ae5bba2a407ac1e48eb"}}
{"timestamp":1768861060989,"type":"book","data":{"type":"book","timestamp":1768861060989,"asset_id":"113421581696345614187888921984273009220039924345606711784540408098901651166996","market":"0x8884313775cb4f37d3de3fa1e9afc797d9d0fb72cae523fbfa7853fab179d500","bids":[],"asks":[[0.999,99999],[0.998,55000],[0.992,155],[0.991,56055],[0.99,27000],[0.989,155],[0.98,1400],[0.95,1300],[0.94,5.51],[0.92,155],[0.903,100],[0.902,10600],[0.901,100],[0.9,3650],[0.86,50],[0.85,450],[0.849,200],[0.848,657],[0.8,50],[0.73,50],[0.66,50],[0.53,100],[0.51,100],[0.503,200],[0.502,1500],[0.501,100],[0.498,398],[0.25,60],[0.233,60],[0.232,572],[0.231,60],[0.23,60],[0.229,25],[0.196,41.57],[0.01,11908.49],[0.009,704.54],[0.008,50.4],[0.007,45.31],[0.006,40.24],[0.005,35.17],[0.004,30.12],[0.003,25.07],[0.002,20.04],[0.001,946.28]],"hash":"2e8d24bf209d8447cdfc0ab2a9bd9574e39783ad"}}
{"timestamp":1768861060993,"type":"book","data":{"type":"book","timestamp":1768861060993,"asset_id":"49335016365941641409952976129113215306810130872796911770220968674695550227620","market":"0xa8e21d98ce3635fdafa916aa404f8dfd4eb941ec5a36e54b07f9fef1dcfa9051","bids":[[0.001,14.99],[0.01,50],[0.011,9090],[0.012,16666],[0.052,25],[0.053,5.51],[0.108,24.37],[0.109,25],[0.11,5.51]],"asks":[],"hash":"7087c964811e8e28ec58b6fe66143e82968d10ca"}}
{"timestamp":1768861060993,"type":"book","data":{"type":"book","timestamp":1768861060993,"asset_id":"107120935694512385169050114827872789982020807731131881827825052191609346273122","market":"0x55bc05d0172e01f468ee39bf260c7fd132b4453c71a37d1834c5c7cce3db5a2e","bids":[],"asks":[[0.99,50],[0.98,5000],[0.94,3363.51],[0.73,58.2],[0.72,17.4],[0.71,25]],"hash":"07ae5e2e79883856f1ac58e31e828ef140cf2a22"}}
{"timestamp":1768861060996,"type":"book","data":{"type":"book","timestamp":1768861060996,"asset_id":"80955465573788561519287799238070819726068512211014816914447962346674298193040","market":"0x8884313775cb4f37d3de3fa1e9afc797d9d0fb72cae523fbfa7853fab179d500","bids":[[0.001,99999],[0.002,55000],[0.008,155],[0.009,56055],[0.01,27000],[0.011,155],[0.02,1400],[0.05,1300],[0.06,5.51],[0.08,155],[0.097,100],[0.098,10600],[0.099,100],[0.1,3650],[0.14,50],[0.15,450],[0.151,200],[0.152,657],[0.2,50],[0.27,50],[0.34,50],[0.47,100],[0.49,100],[0.497,200],[0.498,1500],[0.499,100],[0.502,398],[0.75,60],[0.767,60],[0.768,572],[0.769,60],[0.77,60],[0.771,25],[0.804,41.57],[0.99,11908.49],[0.991,704.54],[0.992,50.4],[0.993,45.31],[0.994,40.24],[0.995,35.17],[0.996,30.12],[0.997,25.07],[0.998,20.04],[0.999,946.28]],"asks":[],"hash":"d41b678042988b4bb0d24d923b9a073a9aa05356"}}
{"timestamp":1768861060997,"type":"book","data":{"type":"book","timestamp":1768861060997,"asset_id":"60854482386705306074271452945147814262686505626338572994501795906620218532455","market":"0xd832ad310ac0e7586c26de1784c8acb2d9e050ad9a264e2bea6db9c0dc0832ed","bids":[],"asks":[[0.999,99999],[0.998,55000],[0.992,155],[0.991,56055],[0.99,27050],[0.989,155],[0.98,1400],[0.95,1300],[0.92,155],[0.903,100],[0.902,10600],[0.901,100],[0.9,3550],[0.859,1309],[0.53,100],[0.51,100],[0.503,200],[0.502,1500],[0.501,100],[0.496,396],[0.25,60],[0.233,60],[0.231,60],[0.23,60],[0.172,12.92],[0.171,5.72],[0.17,8.27],[0.169,25],[0.168,5.51],[0.01,60],[0.009,704.54],[0.008,50.4],[0.007,45.31],[0.006,40.24],[0.005,35.17],[0.004,30.12],[0.003,25.07],[0.002,20.04],[0.001,5]],"hash":"d25f60603333a8105f73cf9c8c4a4782043a7a5c"}}
{"timestamp":1768861060999,"type":"book","data":{"type":"book","timestamp":1768861060999,"asset_id":"43577718766112357875300730326646730119346466279136183595509365799679832624641","market":"0x676d078b81497e987ad19344ca4e3569f89b4e659f91a545f8e9690d6dfa4b39","bids":[],"asks":[[0.99,50],[0.98,700],[0.94,1696.51],[0.83,1176],[0.4,13.19],[0.38,51.46],[0.37,35.34],[0.36,5.51]],"hash":"0f2d660937d8a34e67cffee7bd98240490124519"}}
{"timestamp":1768861061002,"type":"book","data":{"type":"book","timestamp":1768861061002,"asset_id":"7360690154955731738072833984462694862220283551111167441524929099080928304759","market":"0x55bc05d0172e01f468ee39bf260c7fd132b4453c71a37d1834c5c7cce3db5a2e","bids":[[0.01,50],[0.02,5000],[0.06,3363.51],[0.27,58.2],[0.28,17.4],[0.29,25]],"asks":[],"hash":"a5bfe6ffa59105c575bf1c6b3589b35ac35c7782"}}
{"timestamp":1768861061003,"type":"book","data":{"type":"book","timestamp":1768861061003,"asset_id":"43563596164617197569984035984240875096743987893839105155156535794052660412514","market":"0xca03f1e4e2a81ed9d91331e4354e4f07fd1f897dd400f41f810d6db09e8b7a83","bids":[[0.01,50],[0.02,25],[0.03,5.51]],"asks":[],"hash":"61781cef34f83dbd785ce7abf3faa76c2bb5ab6c"}}
{"timestamp":1768861061003,"type":"book","data":{"type":"book","timestamp":1768861061003,"asset_id":"104561417469280438624857704713303730213235315036975837304809065111097458149113","market":"0x74359b1889c9b4f5a84c1cac8cfd2dd6f48731fedb44f7a7e803b9c8cd6de6d8","bids":[],"asks":[[0.999,99999],[0.998,55000],[0.992,155],[0.991,56055],[0.99,27000],[0.989,155],[0.98,2100],[0.97,300],[0.95,200],[0.92,255],[0.903,100],[0.902,10600],[0.901,100],[0.9,3650],[0.86,50],[0.85,450],[0.849,200],[0.848,657],[0.8,50],[0.73,50],[0.66,50],[0.53,100],[0.51,100],[0.503,200],[0.502,1500],[0.501,100],[0.498,398],[0.25,60],[0.233,60],[0.232,571],[0.231,60],[0.23,60],[0.178,23.32],[0.177,25],[0.176,19.53],[0.175,11.02],[0.01,2000],[0.009,644],[0.001,5]],"hash":"e0ae002d7f12f91e401b19cbce68d40698f59811"}}
{"timestamp":1768861061004,"type":"book","data":{"type":"book","timestamp":1768861061004,"asset_id":"111436004474608829181688199751793007557865850840578909060278133660760146801937","market":"0xca03f1e4e2a81ed9d91331e4354e4f07fd1f897dd400f41f810d6db09e8b7a83","bids":[],"asks":[[0.99,50],[0.98,25],[0.97,5.51]],"hash":"35f0f1896cf1c015d6e4f2f0de592310c44e27b8"}}
{"timestamp":1768861061005,"type":"book","data":{"type":"book","timestamp":1768861061005,"asset_id":"38249703376174183440478117641561819852912686676086886922395617711410224047669","market":"0x366ea8dd3a7f8672384fcd74ddbb3001a7798ce9d32fb08e6bf8c538c7e6798f","bids":[[0.001,514.99],[0.01,50],[0.02,1100],[0.06,830.51],[0.11,3310.08],[0.111,25],[0.31,8.52],[0.99,100.51]],"asks":[],"hash":"b966c9263ed5ac619978e0164fcc8ecd2ea2445c"}}
{"timestamp":1768861061005,"type":"book","data":{"type":"book","timestamp":1768861061005,"asset_id":"109974464011407510311184872783466711205513981066359875513765218021885225826488","market":"0xd832ad310ac0e7586c26de1784c8acb2d9e050ad9a264e2bea6db9c0dc0832ed","bids":[[0.001,99999],[0.002,55000],[0.008,155],[0.009,56055],[0.01,27050],[0.011,155],[0.02,1400],[0.05,1300],[0.08,155],[0.097,100],[0.098,10600],[0.099,100],[0.1,3550],[0.141,1309],[0.47,100],[0.49,100],[0.497,200],[0.498,1500],[0.499,100],[0.504,396],[0.75,60],[0.767,60],[0.769,60],[0.77,60],[0.828,12.92],[0.829,5.72],[0.83,8.27],[0.831,25],[0.832,5.51],[0.99,60],[0.991,704.54],[0.992,50.4],[0.993,45.31],[0.994,40.24],[0.995,35.17],[0.996,30.12],[0.997,25.07],[0.998,20.04],[0.999,5]],"asks":[],"hash":"3dbdb7d39b1bcbc5e9bcd085f2cf6e469a05ad83"}}
{"timestamp":1768861061006,"type":"book","data":{"type":"book","timestamp":1768861061006,"asset_id":"45580499855571815703798438949570518410899588907349508423148937057071386680821","market":"0xbe7dc7ab76f592bc89d6c6c606e28d119cb90dd503bd543c61d79d8c2cb18d0d","bids":[[0.001,99999],[0.002,55000],[0.008,155],[0.009,56055],[0.01,27050],[0.011,155],[0.02,2100],[0.03,300],[0.05,200],[0.08,255],[0.097,100],[0.098,10600],[0.099,100],[0.1,3650],[0.14,50],[0.15,450],[0.151,200],[0.152,657],[0.2,50],[0.27,50],[0.34,50],[0.47,100],[0.49,100],[0.497,200],[0.498,1500],[0.499,100],[0.502,398],[0.75,60],[0.767,60],[0.768,219],[0.769,60],[0.77,60],[0.771,47.68],[0.772,5.51],[0.99,2060],[0.991,704.54],[0.992,50.4],[0.993,45.31],[0.994,40.24],[0.995,35.17],[0.996,30.12],[0.997,25.07],[0.998,20.04],[0.999,5]],"asks":[],"hash":"93167f538f8f2977bb0c17ba0d3a8518806ed1f0"}}
{"timestamp":1768861061008,"type":"book","data":{"type":"book","timestamp":1768861061008,"asset_id":"49637045107561300232921209964038170407460446885617809869047360275570604727981","market":"0x366ea8dd3a7f8672384fcd74ddbb3001a7798ce9d32fb08e6bf8c538c7e6798f","bids":[],"asks":[[0.999,514.99],[0.99,50],[0.98,1100],[0.94,830.51],[0.89,3310.08],[0.889,25],[0.69,8.52],[0.01,100.51]],"hash":"1c29ed33736eaa61167745b790705aa340bc1b5d"}}
{"timestamp":1768861061008,"type":"book","data":{"type":"book","timestamp":1768861061008,"asset_id":"85356151034142958812118326873548413742312509549787317293018964257573037506843","market":"0x2bf2d7f54a03b4b01cff5a9e010a7fa7c0532f40f111cc19050c4b7499794f87","bids":[[0.01,100],[0.02,5000],[0.04,62],[0.05,55],[0.06,3338.51],[0.1,13.66],[0.11,31.73],[0.12,25]],"asks":[],"hash":"0763063a33a3303009e05097056373a2196d6d1f"}}
{"timestamp":1768861061009,"type":"book","data":{"type":"book","timestamp":1768861061009,"asset_id":"93658466248405584999260870388818827582402881579193486826612628010719686456341","market":"0x0afef6598f68b1b2d47bca956116bbaa7d11f39d665f883aae5cc126c8e991c9","bids":[],"asks":[[0.999,14.99],[0.99,50],[0.98,25],[0.979,45],[0.976,15],[0.975,15],[0.974,15],[0.972,15],[0.95,5.51],[0.947,1886],[0.946,3703],[0.883,13.12],[0.01,82.39]],"hash":"d3e752a32d9aba114d5a106e254f857fa0f93182"}}
{"timestamp":1768861061013,"type":"book","data":{"type":"book","timestamp":1768861061013,"asset_id":"89196817534650214518343470810012288381453951103093009932230380153906165978759","market":"0x5b588025b5d3cf45804912af31eb2a07577931c00213aba7c23c6e3ad3931672","bids":[[0.001,14.99],[0.01,55.51],[0.03,25],[0.06,30.51],[0.07,75.61],[0.071,25],[0.99,11.79]],"asks":[],"hash":"1a4f4568f6706a35b542c55d257eafd1f831e7a4"}}
{"timestamp":1768861061013,"type":"book","data":{"type":"book","timestamp":1768861061013,"asset_id":"90508786464936430054960174057014699141737305916344517232838682389750156463791","market":"0x74359b1889c9b4f5a84c1cac8cfd2dd6f48731fedb44f7a7e803b9c8cd6de6d8","bids":[[0.001,99999],[0.002,55000],[0.008,155],[0.009,56055],[0.01,27000],[0.011,155],[0.02,2100],[0.03,300],[0.05,200],[0.08,255],[0.097,100],[0.098,10600],[0.099,100],[0.1,3650],[0.14,50],[0.15,450],[0.151,200],[0.152,657],[0.2,50],[0.27,50],[0.34,50],[0.47,100],[0.49,100],[0.497,200],[0.498,1500],[0.499,100],[0.502,398],[0.75,60],[0.767,60],[0.768,571],[0.769,60],[0.77,60],[0.822,23.32],[0.823,25],[0.824,19.53],[0.825,11.02],[0.99,2000],[0.991,644],[0.999,5]],"asks":[],"hash":"b06b3c9017b4409e32c27245f74d134864829222"}}
{"timestamp":1768861061013,"type":"book","data":{"type":"book","timestamp":1768861061013,"asset_id":"1338443871756370759655533003784332150179102079166042651190409012460654731030","market":"0x2bf2d7f54a03b4b01cff5a9e010a7fa7c0532f40f111cc19050c4b7499794f87","bids":[],"asks":[[0.99,100],[0.98,5000],[0.96,62],[0.95,55],[0.94,3338.51],[0.9,13.66],[0.89,31.73],[0.88,25]],"hash":"f44977b434b0d2c0bc5cd9c6e3f9fa81409837f1"}}
{"timestamp":1768861061013,"type":"book","data":{"type":"book","timestamp":1768861061013,"asset_id":"74774623971709706821569763625609154232615320360891965400140251966412790258500","market":"0x994852b813326db703afc598ac97f4baec56a0e9da0e586d9a0154f8b146df28","bids":[],"asks":[[0.99,50],[0.98,5000],[0.94,3363.51],[0.75,51.04],[0.74,16.74],[0.73,25]],"hash":"a4e4d11ac57cf430d644765a8e41998c8fa1702a"}}
{"timestamp":1768861061013,"type":"book","data":{"type":"book","timestamp":1768861061013,"asset_id":"15633387036100115266322094291506265989553265793281973176905404845199622381518","market":"0x5b588025b5d3cf45804912af31eb2a07577931c00213aba7c23c6e3ad3931672","bids":[],"asks":[[0.999,14.99],[0.99,55.51],[0.97,25],[0.94,30.51],[0.93,75.61],[0.929,25],[0.01,11.79]],"hash":"3e139b4ccf58e3a3abfc2a401bf8e41763358e56"}}
{"timestamp":1768861061014,"type":"book","data":{"type":"book","timestamp":1768861061014,"asset_id":"51640950844529073540440468921446646609840378218681177771835773486695222195363","market":"0xbe7dc7ab76f592bc89d6c6c606e28d119cb90dd503bd543c61d79d8c2cb18d0d","bids":[],"asks":[[0.999,99999],[0.998,55000],[0.992,155],[0.991,56055],[0.99,27050],[0.989,155],[0.98,2100],[0.97,300],[0.95,200],[0.92,255],[0.903,100],[0.902,10600],[0.901,100],[0.9,3650],[0.86,50],[0.85,450],[0.849,200],[0.848,657],[0.8,50],[0.73,50],[0.66,50],[0.53,100],[0.51,100],[0.503,200],[0.502,1500],[0.501,100],[0.498,398],[0.25,60],[0.233,60],[0.232,219],[0.231,60],[0.23,60],[0.229,47.68],[0.228,5.51],[0.01,2060],[0.009,704.54],[0.008,50.4],[0.007,45.31],[0.006,40.24],[0.005,35.17],[0.004,30.12],[0.003,25.07],[0.002,20.04],[0.001,5]],"hash":"12a94c2cb8c2fc38ab538fe16577ec33a100471d"}}
{"timestamp":1768861061014,"type":"book","data":{"type":"book","timestamp":1768861061014,"asset_id":"98888987637702944200466394029062132161347270306418627034681906287677121368389","market":"0x29067ebc925c8bb2d14f0bb8c7946005e51538109dc2e4d201639a40232bc93c","bids":[],"asks":[[0.99,50],[0.98,25],[0.97,5.51]],"hash":"e312f981aaf4e3a2a05501a8561d4fb86e5a9326"}}
{"timestamp":1768861061014,"type":"book","data":{"type":"book","timestamp":1768861061014,"asset_id":"5689681855689828399428106754866979922401730116817121622527657120513897525909","market":"0x994852b813326db703afc598ac97f4baec56a0e9da0e586d9a0154f8b146df28","bids":[[0.01,50],[0.02,5000],[0.06,3363.51],[0.25,51.04],[0.26,16.74],[0.27,25]],"asks":[],"hash":"76542d356b15b3be235fbf801667df668ed825de"}}
{"timestamp":1768861061014,"type":"book","data":{"type":"book","timestamp":1768861061014,"asset_id":"23982213020675018791507326977308149379200692959141537028293395142867568952427","market":"0x0afef6598f68b1b2d47bca956116bbaa7d11f39d665f883aae5cc126c8e991c9","bids":[[0.001,14.99],[0.01,50],[0.02,25],[0.021,45],[0.024,15],[0.025,15],[0.026,15],[0.028,15],[0.05,5.51],[0.053,1886],[0.054,3703],[0.117,13.12],[0.99,82.39]],"asks":[],"hash":"cf1f63da2509690e11ecb35322e5e12cee9e2ff8"}}
{"timestamp":1768861064624,"type":"book","data":{"type":"book","timestamp":1768861064624,"asset_id":"7360690154955731738072833984462694862220283551111167441524929099080928304759","market":"0x55bc05d0172e01f468ee39bf260c7fd132b4453c71a37d1834c5c7cce3db5a2e","bids":[[0.01,50],[0.02,5000],[0.06,2113.51],[0.27,75.6],[0.29,25]],"asks":[],"hash":"ff7799de6ff5cf940ead074b49447f55d7727b7b"}}
{"timestamp":1768861064625,"type":"book","data":{"type":"book","timestamp":1768861064625,"asset_id":"90508786464936430054960174057014699141737305916344517232838682389750156463791","market":"0x74359b1889c9b4f5a84c1cac8cfd2dd6f48731fedb44f7a7e803b9c8cd6de6d8","bids":[[0.001,99999],[0.002,55000],[0.008,155],[0.009,56055],[0.01,27000],[0.011,155],[0.02,2100],[0.03,300],[0.05,200],[0.08,255],[0.097,100],[0.098,10600],[0.099,100],[0.1,3650],[0.14,50],[0.15,450],[0.151,200],[0.152,657],[0.2,50],[0.27,50],[0.34,50],[0.47,100],[0.49,100],[0.497,200],[0.498,1500],[0.499,100],[0.503,248],[0.75,60],[0.767,60],[0.768,571],[0.769,60],[0.77,60],[0.822,23.32],[0.823,25],[0.824,19.53],[0.825,11.02],[0.99,2000],[0.991,644],[0.999,5]],"asks":[],"hash":"3714fb2ba76bf8ddc009f32ccdf51b47f69770b5"}}
{"timestamp":1768861064625,"type":"book","data":{"type":"book","timestamp":1768861064625,"asset_id":"5689681855689828399428106754866979922401730116817121622527657120513897525909","market":"0x994852b813326db703afc598ac97f4baec56a0e9da0e586d9a0154f8b146df28","bids":[[0.01,50],[0.02,5000],[0.06,2113.51],[0.25,67.78],[0.27,25]],"asks":[],"hash":"39b03afb682fa4e04b5bf39ec207dcd3718f90b7"}}
{"timestamp":1768861064625,"type":"book","data":{"type":"book","timestamp":1768861064625,"asset_id":"109974464011407510311184872783466711205513981066359875513765218021885225826488","market":"0xd832ad310ac0e7586c26de1784c8acb2d9e050ad9a264e2bea6db9c0dc0832ed","bids":[[0.001,99999],[0.002,55000],[0.008,155],[0.009,56055],[0.01,27050],[0.011,155],[0.02,1400],[0.05,1300],[0.08,155],[0.097,100],[0.098,10600],[0.099,100],[0.1,3550],[0.141,1309],[0.47,100],[0.49,100],[0.497,200],[0.498,1500],[0.499,100],[0.505,247],[0.75,60],[0.767,60],[0.769,60],[0.77,60],[0.828,26.92],[0.831,25],[0.832,5.51],[0.99,60],[0.991,704.54],[0.992,50.4],[0.993,45.31],[0.994,40.24],[0.995,35.17],[0.996,30.12],[0.997,25.07],[0.998,20.04],[0.999,5]],"asks":[],"hash":"89dc79e71c3f8ba3b69fcf3ae689ea2b7691db2f"}}
{"timestamp":1768861064625,"type":"book","data":{"type":"book","timestamp":1768861064625,"asset_id":"80955465573788561519287799238070819726068512211014816914447962346674298193040","market":"0x8884313775cb4f37d3de3fa1e9afc797d9d0fb72cae523fbfa7853fab179d500","bids":[[0.001,99999],[0.002,55000],[0.008,155],[0.009,56055],[0.01,27000],[0.011,155],[0.02,1400],[0.05,1300],[0.06,5.51],[0.08,155],[0.097,100],[0.098,10600],[0.099,100],[0.1,3650],[0.14,50],[0.15,450],[0.151,200],[0.152,657],[0.2,50],[0.27,50],[0.34,50],[0.47,100],[0.49,100],[0.497,200],[0.498,1500],[0.499,100],[0.503,248],[0.75,60],[0.767,60],[0.768,572],[0.769,60],[0.77,60],[0.771,25],[0.804,41.57],[0.99,11908.49],[0.991,704.54],[0.992,50.4],[0.993,45.31],[0.994,40.24],[0.995,35.17],[0.996,30.12],[0.997,25.07],[0.998,20.04],[0.999,946.28]],"asks":[],"hash":"4e632ca725c8fce1ea4034147104df7e23dc641c"}}
{"timestamp":1768861064625,"type":"book","data":{"type":"book","timestamp":1768861064625,"asset_id":"93658466248405584999260870388818827582402881579193486826612628010719686456341","market":"0x0afef6598f68b1b2d47bca956116bbaa7d11f39d665f883aae5cc126c8e991c9","bids":[],"asks":[[0.999,14.99],[0.99,50],[0.98,25],[0.979,45],[0.976,15],[0.975,15],[0.974,15],[0.972,15],[0.95,5.51],[0.945,4090],[0.883,13.12],[0.01,82.39]],"hash":"0d73835a13c4f40a42c55faef8f277d30bb70ff5"}}
{"timestamp":1768861064626,"type":"book","data":{"type":"book","timestamp":1768861064626,"asset_id":"113421581696345614187888921984273009220039924345606711784540408098901651166996","market":"0x8884313775cb4f37d3de3fa1e9afc797d9d0fb72cae523fbfa7853fab179d500","bids":[],"asks":[[0.999,99999],[0.998,55000],[0.992,155],[0.991,56055],[0.99,27000],[0.989,155],[0.98,1400],[0.95,1300],[0.94,5.51],[0.92,155],[0.903,100],[0.902,10600],[0.901,100],[0.9,3650],[0.86,50],[0.85,450],[0.849,200],[0.848,657],[0.8,50],[0.73,50],[0.66,50],[0.53,100],[0.51,100],[0.503,200],[0.502,1500],[0.501,100],[0.497,248],[0.25,60],[0.233,60],[0.232,572],[0.231,60],[0.23,60],[0.229,25],[0.196,41.57],[0.01,11908.49],[0.009,704.54],[0.008,50.4],[0.007,45.31],[0.006,40.24],[0.005,35.17],[0.004,30.12],[0.003,25.07],[0.002,20.04],[0.001,946.28]],"hash":"5f74318678424da5f2b114cc51550a1629547c7b"}}
{"timestamp":1768861064626,"type":"book","data":{"type":"book","timestamp":1768861064626,"asset_id":"107120935694512385169050114827872789982020807731131881827825052191609346273122","market":"0x55bc05d0172e01f468ee39bf260c7fd132b4453c71a37d1834c5c7cce3db5a2e","bids":[],"asks":[[0.99,50],[0.98,5000],[0.94,2113.51],[0.73,75.6],[0.71,25]],"hash":"6f50bf63ab5e6d0e8ffa8689a350bc2cb65df5c7"}}
{"timestamp":1768861064626,"type":"book","data":{"type":"book","timestamp":1768861064626,"asset_id":"23982213020675018791507326977308149379200692959141537028293395142867568952427","market":"0x0afef6598f68b1b2d47bca956116bbaa7d11f39d665f883aae5cc126c8e991c9","bids":[[0.001,14.99],[0.01,50],[0.02,25],[0.021,45],[0.024,15],[0.025,15],[0.026,15],[0.028,15],[0.05,5.51],[0.055,4090],[0.117,13.12],[0.99,82.39]],"asks":[],"hash":"2d274bf9a6a6ba909f4d51330d4ab02f6979e836"}}
{"timestamp":1768861064628,"type":"book","data":{"type":"book","timestamp":1768861064628,"asset_id":"105946555319717952586004333254949548955829524636247831439729957976174835757796","market":"0x29067ebc925c8bb2d14f0bb8c7946005e51538109dc2e4d201639a40232bc93c","bids":[[0.01,50],[0.02,25],[0.03,5.51]],"asks":[],"hash":"0de2ce2270694551c2f65ae5bba2a407ac1e48eb"}}
{"timestamp":1768861064628,"type":"book","data":{"type":"book","timestamp":1768861064628,"asset_id":"43577718766112357875300730326646730119346466279136183595509365799679832624641","market":"0x676d078b81497e987ad19344ca4e3569f89b4e659f91a545f8e9690d6dfa4b39","bids":[],"asks":[[0.99,50],[0.98,700],[0.94,1696.51],[0.82,694],[0.4,5.28],[0.39,23.22],[0.37,32.44],[0.36,5.51]],"hash":"422b61526f8a742b9de24a20cc5b20de4f9191c2"}}
{"timestamp":1768861064628,"type":"book","data":{"type":"book","timestamp":1768861064628,"asset_id":"111436004474608829181688199751793007557865850840578909060278133660760146801937","market":"0xca03f1e4e2a81ed9d91331e4354e4f07fd1f897dd400f41f810d6db09e8b7a83","bids":[],"asks":[[0.99,50],[0.98,25],[0.97,5.51]],"hash":"35f0f1896cf1c015d6e4f2f0de592310c44e27b8"}}
{"timestamp":1768861064628,"type":"book","data":{"type":"book","timestamp":1768861064628,"asset_id":"60854482386705306074271452945147814262686505626338572994501795906620218532455","market":"0xd832ad310ac0e7586c26de1784c8acb2d9e050ad9a264e2bea6db9c0dc0832ed","bids":[],"asks":[[0.999,99999],[0.998,55000],[0.992,155],[0.991,56055],[0.99,27050],[0.989,155],[0.98,1400],[0.95,1300],[0.92,155],[0.903,100],[0.902,10600],[0.901,100],[0.9,3550],[0.859,1309],[0.53,100],[0.51,100],[0.503,200],[0.502,1500],[0.501,100],[0.495,247],[0.25,60],[0.233,60],[0.231,60],[0.23,60],[0.172,26.92],[0.169,25],[0.168,5.51],[0.01,60],[0.009,704.54],[0.008,50.4],[0.007,45.31],[0.006,40.24],[0.005,35.17],[0.004,30.12],[0.003,25.07],[0.002,20.04],[0.001,5]],"hash":"bf5da9dd93cabb18eb39264a42dc3a211d143425"}}
{"timestamp":1768861064629,"type":"book","data":{"type":"book","timestamp":1768861064629,"asset_id":"85356151034142958812118326873548413742312509549787317293018964257573037506843","market":"0x2bf2d7f54a03b4b01cff5a9e010a7fa7c0532f40f111cc19050c4b7499794f87","bids":[[0.01,100],[0.02,5000],[0.04,62],[0.05,2555],[0.06,5.51],[0.1,36.64],[0.11,17],[0.12,25]],"asks":[],"hash":"d1d669779021e6ca47b02bb90e34f7e0b903252c"}}
{"timestamp":1768861064631,"type":"book","data":{"type":"book","timestamp":1768861064631,"asset_id":"9031636498902109489531840330955202379047865759768140186724288939684833165378","market":"0x676d078b81497e987ad19344ca4e3569f89b4e659f91a545f8e9690d6dfa4b39","bids":[[0.01,50],[0.02,700],[0.06,1696.51],[0.18,694],[0.6,5.28],[0.61,23.22],[0.63,32.44],[0.64,5.51]],"asks":[],"hash":"621b29c275b759f13c6626c15490a5a6bc8050e4"}}
{"timestamp":1768861064633,"type":"book","data":{"type":"book","timestamp":1768861064633,"asset_id":"1338443871756370759655533003784332150179102079166042651190409012460654731030","market":"0x2bf2d7f54a03b4b01cff5a9e010a7fa7c0532f40f111cc19050c4b7499794f87","bids":[],"asks":[[0.99,100],[0.98,5000],[0.96,62],[0.95,2555],[0.94,5.51],[0.9,36.64],[0.89,17],[0.88,25]],"hash":"a2f6d92f5cb400225a506a40c1304198c49bc797"}}
{"timestamp":1768861064638,"type":"book","data":{"type":"book","timestamp":1768861064638,"asset_id":"83762004711915891788797964319803421904923212191800334283779459846638388049876","market":"0xa8e21d98ce3635fdafa916aa404f8dfd4eb941ec5a36e54b07f9fef1dcfa9051","bids":[],"asks":[[0.999,14.99],[0.99,50],[0.987,7692],[0.948,25],[0.947,5.51],[0.892,24.37],[0.891,25],[0.89,5.51]],"hash":"ea33cc1263b88e0b66431117c786d09b59573dfd"}}
{"timestamp":1768861064638,"type":"book","data":{"type":"book","timestamp":1768861064638,"asset_id":"51640950844529073540440468921446646609840378218681177771835773486695222195363","market":"0xbe7dc7ab76f592bc89d6c6c606e28d119cb90dd503bd543c61d79d8c2cb18d0d","bids":[],"asks":[[0.999,99999],[0.998,55000],[0.992,155],[0.991,56055],[0.99,27050],[0.989,155],[0.98,2100],[0.97,300],[0.95,200],[0.92,255],[0.903,100],[0.902,10600],[0.901,100],[0.9,3650],[0.86,50],[0.85,450],[0.849,200],[0.848,657],[0.8,50],[0.73,50],[0.66,50],[0.53,100],[0.51,100],[0.503,200],[0.502,1500],[0.501,100],[0.497,248],[0.25,60],[0.233,60],[0.232,219],[0.231,60],[0.23,60],[0.229,47.68],[0.228,5.51],[0.01,2060],[0.009,704.54],[0.008,50.4],[0.007,45.31],[0.006,40.24],[0.005,35.17],[0.004,30.12],[0.003,25.07],[0.002,20.04],[0.001,5]],"hash":"facab0cf4cf04b97ae4c043729a651291d1b975f"}}
{"timestamp":1768861064639,"type":"book","data":{"type":"book","timestamp":1768861064639,"asset_id":"98888987637702944200466394029062132161347270306418627034681906287677121368389","market":"0x29067ebc925c8bb2d14f0bb8c7946005e51538109dc2e4d201639a40232bc93c","bids":[],"asks":[[0.99,50],[0.98,25],[0.97,5.51]],"hash":"e312f981aaf4e3a2a05501a8561d4fb86e5a9326"}}
{"timestamp":1768861064639,"type":"book","data":{"type":"book","timestamp":1768861064639,"asset_id":"74774623971709706821569763625609154232615320360891965400140251966412790258500","market":"0x994852b813326db703afc598ac97f4baec56a0e9da0e586d9a0154f8b146df28","bids":[],"asks":[[0.99,50],[0.98,5000],[0.94,2113.51],[0.75,67.78],[0.73,25]],"hash":"b2188144b5322d2bc902a7156d2ce7cd6d15e131"}}
{"timestamp":1768861064639,"type":"book","data":{"type":"book","timestamp":1768861064639,"asset_id":"104561417469280438624857704713303730213235315036975837304809065111097458149113","market":"0x74359b1889c9b4f5a84c1cac8cfd2dd6f48731fedb44f7a7e803b9c8cd6de6d8","bids":[],"asks":[[0.999,99999],[0.998,55000],[0.992,155],[0.991,56055],[0.99,27000],[0.989,155],[0.98,2100],[0.97,300],[0.95,200],[0.92,255],[0.903,100],[0.902,10600],[0.901,100],[0.9,3650],[0.86,50],[0.85,450],[0.849,200],[0.848,657],[0.8,50],[0.73,50],[0.66,50],[0.53,100],[0.51,100],[0.503,200],[0.502,1500],[0.501,100],[0.497,248],[0.25,60],[0.233,60],[0.232,571],[0.231,60],[0.23,60],[0.178,23.32],[0.177,25],[0.176,19.53],[0.175,11.02],[0.01,2000],[0.009,644],[0.001,5]],"hash":"d92c386326217e68f34ec02853a4b22301f675c0"}}
{"timestamp":1768861064639,"type":"book","data":{"type":"book","timestamp":1768861064639,"asset_id":"45580499855571815703798438949570518410899588907349508423148937057071386680821","market":"0xbe7dc7ab76f592bc89d6c6c606e28d119cb90dd503bd543c61d79d8c2cb18d0d","bids":[[0.001,99999],[0.002,55000],[0.008,155],[0.009,56055],[0.01,27050],[0.011,155],[0.02,2100],[0.03,300],[0.05,200],[0.08,255],[0.097,100],[0.098,10600],[0.099,100],[0.1,3650],[0.14,50],[0.15,450],[0.151,200],[0.152,657],[0.2,50],[0.27,50],[0.34,50],[0.47,100],[0.49,100],[0.497,200],[0.498,1500],[0.499,100],[0.503,248],[0.75,60],[0.767,60],[0.768,219],[0.769,60],[0.77,60],[0.771,47.68],[0.772,5.51],[0.99,2060],[0.991,704.54],[0.992,50.4],[0.993,45.31],[0.994,40.24],[0.995,35.17],[0.996,30.12],[0.997,25.07],[0.998,20.04],[0.999,5]],"asks":[],"hash":"939d00123336ce2f34e755f2fb1ccb8fcffdf79a"}}
{"timestamp":1768861064641,"type":"book","data":{"type":"book","timestamp":1768861064641,"asset_id":"43563596164617197569984035984240875096743987893839105155156535794052660412514","market":"0xca03f1e4e2a81ed9d91331e4354e4f07fd1f897dd400f41f810d6db09e8b7a83","bids":[[0.01,50],[0.02,25],[0.03,5.51]],"asks":[],"hash":"61781cef34f83dbd785ce7abf3faa76c2bb5ab6c"}}
{"timestamp":1768861064641,"type":"book","data":{"type":"book","timestamp":1768861064641,"asset_id":"49335016365941641409952976129113215306810130872796911770220968674695550227620","market":"0xa8e21d98ce3635fdafa916aa404f8dfd4eb941ec5a36e54b07f9fef1dcfa9051","bids":[[0.001,14.99],[0.01,50],[0.013,7692],[0.052,25],[0.053,5.51],[0.108,24.37],[0.109,25],[0.11,5.51]],"asks":[],"hash":"5d1e973e378bf87364130663c1dd8678f5d61c4f"}}
