{"timestamp":1768863369408,"type":"book","data":{"type":"book","timestamp":1768863369408,"asset_id":"9031636498902109489531840330955202379047865759768140186724288939684833165378","market":"161587","bids":[[0.001,14.99],[0.01,50],[0.45,74.99],[0.451,30.51]],"asks":[]}}
{"timestamp":1768863369544,"type":"book","data":{"type":"book","timestamp":1768863369544,"asset_id":"43577718766112357875300730326646730119346466279136183595509365799679832624641","market":"161587","bids":[],"asks":[[0.999,14.99],[0.99,50],[0.55,74.99],[0.549,30.51]]}}
{"timestamp":1768863369677,"type":"book","data":{"type":"book","timestamp":1768863369677,"asset_id":"5689681855689828399428106754866979922401730116817121622527657120513897525909","market":"161587","bids":[[0.01,7050],[0.08,55],[0.1,500],[0.24,30.29],[0.28,37.5],[0.29,25]],"asks":[]}}
{"timestamp":1768863369814,"type":"book","data":{"type":"book","timestamp":1768863369814,"asset_id":"74774623971709706821569763625609154232615320360891965400140251966412790258500","market":"161587","bids":[],"asks":[[0.99,7050],[0.92,55],[0.9,500],[0.76,30.29],[0.72,37.5],[0.71,25]]}}
{"timestamp":1768863369995,"type":"book","data":{"type":"book","timestamp":1768863369995,"asset_id":"7360690154955731738072833984462694862220283551111167441524929099080928304759","market":"161587","bids":[[0.001,5000],[0.002,55000],[0.008,155],[0.01,27550],[0.011,155],[0.02,2100],[0.05,200],[0.08,255],[0.097,100],[0.099,100],[0.1,4000],[0.118,550],[0.29,75.61],[0.47,100],[0.49,100],[0.497,200],[0.499,100],[0.75,60],[0.767,60],[0.769,60],[0.77,60],[0.771,25],[0.991,500],[0.992,5.51]],"asks":[]}}
{"timestamp":1768863370134,"type":"book","data":{"type":"book","timestamp":1768863370134,"asset_id":"107120935694512385169050114827872789982020807731131881827825052191609346273122","market":"161587","bids":[],"asks":[[0.999,5000],[0.998,55000],[0.992,155],[0.99,27550],[0.989,155],[0.98,2100],[0.95,200],[0.92,255],[0.903,100],[0.901,100],[0.9,4000],[0.882,550],[0.71,75.61],[0.53,100],[0.51,100],[0.503,200],[0.501,100],[0.25,60],[0.233,60],[0.231,60],[0.23,60],[0.229,25],[0.009,500],[0.008,5.51]]}}
{"timestamp":1768863370283,"type":"book","data":{"type":"book","timestamp":1768863370283,"asset_id":"71459940788768289369388827341933628291041428032682324236872093006027462842932","market":"161587","bids":[[0.002,55000],[0.008,155],[0.01,27550],[0.011,155],[0.02,2100],[0.05,200],[0.08,255],[0.097,100],[0.099,100],[0.1,4000],[0.118,550],[0.47,100],[0.475,75.62],[0.49,100],[0.497,200],[0.499,100],[0.75,60],[0.767,60],[0.769,60],[0.77,60],[0.771,25],[0.99,95],[0.991,500],[0.992,10.51]],"asks":[]}}
{"timestamp":1768863370425,"type":"book","data":{"type":"book","timestamp":1768863370425,"asset_id":"23288743695636620381867808278031544648048214106114607887269598951056044003098","market":"161587","bids":[],"asks":[[0.998,55000],[0.992,155],[0.99,27550],[0.989,155],[0.98,2100],[0.95,200],[0.92,255],[0.903,100],[0.901,100],[0.9,4000],[0.882,550],[0.53,100],[0.525,75.62],[0.51,100],[0.503,200],[0.501,100],[0.25,60],[0.233,60],[0.231,60],[0.23,60],[0.229,25],[0.01,95],[0.009,500],[0.008,10.51]]}}
{"timestamp":1768863370570,"type":"book","data":{"type":"book","timestamp":1768863370570,"asset_id":"94285110769567966486463661297410356109827983764157167229272297139989795256953","market":"161587","bids":[[0.002,55000],[0.008,155],[0.01,27550],[0.011,155],[0.02,2100],[0.05,200],[0.08,255],[0.097,100],[0.099,100],[0.1,4000],[0.11,550],[0.47,100],[0.49,100],[0.497,200],[0.499,100],[0.75,60],[0.767,60],[0.769,60],[0.77,60],[0.991,500],[0.992,55.51]],"asks":[]}}
{"timestamp":1768863370738,"type":"book","data":{"type":"book","timestamp":1768863370738,"asset_id":"34367065238487927523900111259648857646009474251375713435120986499501795995070","market":"161587","bids":[],"asks":[[0.998,55000],[0.992,155],[0.99,27550],[0.989,155],[0.98,2100],[0.95,200],[0.92,255],[0.903,100],[0.901,100],[0.9,4000],[0.89,550],[0.53,100],[0.51,100],[0.503,200],[0.501,100],[0.25,60],[0.233,60],[0.231,60],[0.23,60],[0.009,500],[0.008,55.51]]}}
{"timestamp":1768863370885,"type":"book","data":{"type":"book","timestamp":1768863370885,"asset_id":"65238912540593149767509870878968239590124887893827161207600259653260563923070","market":"161587","bids":[],"asks":[[0.99,50],[0.98,30.51]]}}
{"timestamp":1768863371052,"type":"book","data":{"type":"book","timestamp":1768863371052,"asset_id":"52706147105070524363009267529922604376781175933531786990678540409860700140950","market":"161587","bids":[[0.01,50],[0.02,30.51]],"asks":[]}}
{"timestamp":1768863371192,"type":"book","data":{"type":"book","timestamp":1768863371192,"asset_id":"105946555319717952586004333254949548955829524636247831439729957976174835757796","market":"161587","bids":[[0.002,55000],[0.008,155],[0.01,27550],[0.011,155],[0.02,2100],[0.05,200],[0.08,255],[0.097,100],[0.099,100],[0.1,4000],[0.118,550],[0.47,100],[0.49,100],[0.497,200],[0.499,100],[0.5,400],[0.75,60],[0.767,60],[0.769,60],[0.77,60],[0.99,95],[0.991,500],[0.992,30.51]],"asks":[]}}
{"timestamp":1768863371328,"type":"book","data":{"type":"book","timestamp":1768863371328,"asset_id":"98888987637702944200466394029062132161347270306418627034681906287677121368389","market":"161587","bids":[],"asks":[[0.998,55000],[0.992,155],[0.99,27550],[0.989,155],[0.98,2100],[0.95,200],[0.92,255],[0.903,100],[0.901,100],[0.9,4000],[0.882,550],[0.53,100],[0.51,100],[0.503,200],[0.501,100],[0.5,400],[0.25,60],[0.233,60],[0.231,60],[0.23,60],[0.01,95],[0.009,500],[0.008,30.51]]}}
{"timestamp":1768863371466,"type":"book","data":{"type":"book","timestamp":1768863371466,"asset_id":"32000187069377430896265944353073875929784130362721284251736314375740995009132","market":"161587","bids":[[0.001,5000],[0.002,55000],[0.008,155],[0.01,27550],[0.011,155],[0.02,2100],[0.05,200],[0.08,255],[0.097,100],[0.099,100],[0.1,4000],[0.118,550],[0.47,100],[0.49,100],[0.497,200],[0.499,100],[0.5,650],[0.75,159.99],[0.767,60],[0.769,60],[0.77,60],[0.771,25],[0.772,5.51],[0.99,95],[0.991,500]],"asks":[]}}
{"timestamp":1768863371617,"type":"book","data":{"type":"book","timestamp":1768863371617,"asset_id":"72300811647490128998831837378933981624665087909864960667694762257393293709099","market":"161587","bids":[],"asks":[[0.999,5000],[0.998,55000],[0.992,155],[0.99,27550],[0.989,155],[0.98,2100],[0.95,200],[0.92,255],[0.903,100],[0.901,100],[0.9,4000],[0.882,550],[0.53,100],[0.51,100],[0.503,200],[0.501,100],[0.5,650],[0.25,159.99],[0.233,60],[0.231,60],[0.23,60],[0.229,25],[0.228,5.51],[0.01,95],[0.009,500]]}}
{"timestamp":1768863371763,"type":"book","data":{"type":"book","timestamp":1768863371763,"asset_id":"113025031494916309150086220666714068684066916056870600664866463237320949012683","market":"161587","bids":[[0.002,55000],[0.008,155],[0.01,27550],[0.011,155],[0.02,2100],[0.05,200],[0.08,255],[0.097,100],[0.099,100],[0.1,4000],[0.141,550],[0.47,100],[0.49,100],[0.497,200],[0.499,100],[0.5,250],[0.55,427.36],[0.75,60],[0.767,60],[0.769,60],[0.77,60],[0.771,25],[0.772,5.51],[0.99,69.49],[0.991,500]],"asks":[]}}
{"timestamp":1768863371912,"type":"book","data":{"type":"book","timestamp":1768863371912,"asset_id":"106502645861422820101428418410740039040950178042688282565606126950746542596804","market":"161587","bids":[],"asks":[[0.998,55000],[0.992,155],[0.99,27550],[0.989,155],[0.98,2100],[0.95,200],[0.92,255],[0.903,100],[0.901,100],[0.9,4000],[0.859,550],[0.53,100],[0.51,100],[0.503,200],[0.501,100],[0.5,250],[0.45,427.36],[0.25,60],[0.233,60],[0.231,60],[0.23,60],[0.229,25],[0.228,5.51],[0.01,69.49],[0.009,500]]}}
{"timestamp":1768863372112,"type":"book","data":{"type":"book","timestamp":1768863372112,"asset_id":"24085294160146023460801270886062008540816580162480837570482544017068711307043","market":"161587","bids":[],"asks":[[0.998,55000],[0.992,155],[0.99,27550],[0.989,155],[0.98,2100],[0.95,200],[0.92,255],[0.903,100],[0.901,100],[0.9,4000],[0.89,550],[0.53,100],[0.51,100],[0.503,200],[0.501,100],[0.5,650],[0.25,60],[0.233,60],[0.231,60],[0.23,60],[0.229,25],[0.228,11.02],[0.01,35],[0.009,500]]}}
{"timestamp":1768863372256,"type":"book","data":{"type":"book","timestamp":1768863372256,"asset_id":"68660619242068838780359514667334675625428574513507330730861992120392412078977","market":"161587","bids":[[0.002,55000],[0.008,155],[0.01,27550],[0.011,155],[0.02,2100],[0.05,200],[0.08,255],[0.097,100],[0.099,100],[0.1,4000],[0.11,1450],[0.47,100],[0.49,100],[0.497,200],[0.499,100],[0.5,650],[0.75,60],[0.767,60],[0.769,60],[0.77,60],[0.771,25],[0.772,11.02],[0.99,35],[0.991,500]],"asks":[]}}
{"timestamp":1768863372405,"type":"book","data":{"type":"book","timestamp":1768863372405,"asset_id":"71775041801808637972785922632852978725572532275252146056957073487383515608173","market":"161587","bids":[],"asks":[[0.99,50],[0.98,30.51]]}}
{"timestamp":1768863372534,"type":"book","data":{"type":"book","timestamp":1768863372534,"asset_id":"33672246756272849240665557330388834060801478981449620394497796903940273756329","market":"161587","bids":[[0.01,50],[0.02,30.51]],"asks":[]}}
{"timestamp":1768863372676,"type":"book","data":{"type":"book","timestamp":1768863372676,"asset_id":"38249703376174183440478117641561819852912686676086886922395617711410224047669","market":"161587","bids":[[0.002,55000],[0.008,155],[0.01,27550],[0.011,155],[0.02,2100],[0.05,200],[0.08,255],[0.097,100],[0.099,100],[0.1,4000],[0.118,1397],[0.372,17.15],[0.47,100],[0.49,100],[0.497,200],[0.499,100],[0.5,650],[0.75,60],[0.767,60],[0.769,60],[0.77,60],[0.771,25],[0.99,95],[0.991,500],[0.992,5.51]],"asks":[]}}
{"timestamp":1768863372821,"type":"book","data":{"type":"book","timestamp":1768863372821,"asset_id":"49637045107561300232921209964038170407460446885617809869047360275570604727981","market":"161587","bids":[],"asks":[[0.998,55000],[0.992,155],[0.99,27550],[0.989,155],[0.98,2100],[0.95,200],[0.92,255],[0.903,100],[0.901,100],[0.9,4000],[0.882,1397],[0.628,17.15],[0.53,100],[0.51,100],[0.503,200],[0.501,100],[0.5,650],[0.25,60],[0.233,60],[0.231,60],[0.23,60],[0.229,25],[0.01,95],[0.009,500],[0.008,5.51]]}}
{"timestamp":1768863372950,"type":"book","data":{"type":"book","timestamp":1768863372950,"asset_id":"102470506234631856714287226623345182033813197411154001523556742367360332249186","market":"161587","bids":[[0.002,55000],[0.008,155],[0.01,27550],[0.011,155],[0.02,2100],[0.05,200],[0.08,255],[0.097,100],[0.099,100],[0.1,4000],[0.137,20],[0.141,1259],[0.47,100],[0.49,100],[0.497,200],[0.499,100],[0.5,650],[0.75,60],[0.767,60],[0.769,60],[0.77,60],[0.771,25],[0.99,35],[0.991,500],[0.992,10.51]],"asks":[]}}
{"timestamp":1768863373096,"type":"book","data":{"type":"book","timestamp":1768863373096,"asset_id":"31795349211219422607185815612973220690717749068121740516256733008230250593184","market":"161587","bids":[],"asks":[[0.998,55000],[0.992,155],[0.99,27550],[0.989,155],[0.98,2100],[0.95,200],[0.92,255],[0.903,100],[0.901,100],[0.9,4000],[0.863,20],[0.859,1259],[0.53,100],[0.51,100],[0.503,200],[0.501,100],[0.5,650],[0.25,60],[0.233,60],[0.231,60],[0.23,60],[0.229,25],[0.01,35],[0.009,500],[0.008,10.51]]}}
{"timestamp":1768863373297,"type":"book","data":{"type":"book","timestamp":1768863373297,"asset_id":"43563596164617197569984035984240875096743987893839105155156535794052660412514","market":"161587","bids":[[0.002,55000],[0.008,155],[0.01,27550],[0.011,155],[0.02,2100],[0.05,200],[0.08,255],[0.097,100],[0.099,100],[0.1,4000],[0.118,1397],[0.47,100],[0.49,100],[0.497,200],[0.499,100],[0.5,650],[0.75,60],[0.767,60],[0.769,60],[0.77,60],[0.99,95],[0.991,500],[0.992,30.51]],"asks":[]}}
{"timestamp":1768863373445,"type":"book","data":{"type":"book","timestamp":1768863373445,"asset_id":"111436004474608829181688199751793007557865850840578909060278133660760146801937","market":"161587","bids":[],"asks":[[0.998,55000],[0.992,155],[0.99,27550],[0.989,155],[0.98,2100],[0.95,200],[0.92,255],[0.903,100],[0.901,100],[0.9,4000],[0.882,1397],[0.53,100],[0.51,100],[0.503,200],[0.501,100],[0.5,650],[0.25,60],[0.233,60],[0.231,60],[0.23,60],[0.01,95],[0.009,500],[0.008,30.51]]}}
{"timestamp":1768863373590,"type":"book","data":{"type":"book","timestamp":1768863373590,"asset_id":"50983867355616416655423952313122695633917659698391114174631454013985844444839","market":"161587","bids":[],"asks":[[0.999,14.99],[0.99,50]]}}
{"timestamp":1768863373780,"type":"book","data":{"type":"book","timestamp":1768863373780,"asset_id":"57387565809979849367931485811783458230949362028360279464167270926827433389414","market":"161587","bids":[[0.001,14.99],[0.01,50]],"asks":[]}}
{"timestamp":1768863373910,"type":"book","data":{"type":"book","timestamp":1768863373910,"asset_id":"23982213020675018791507326977308149379200692959141537028293395142867568952427","market":"161587","bids":[[0.002,55000],[0.008,155],[0.01,27550],[0.011,155],[0.02,2100],[0.021,45],[0.024,15],[0.025,15],[0.026,15],[0.028,15],[0.05,200],[0.061,13.12],[0.08,255],[0.097,100],[0.099,100],[0.1,4000],[0.118,1397],[0.47,100],[0.49,100],[0.497,200],[0.499,100],[0.5,650],[0.75,60],[0.767,60],[0.769,60],[0.77,60],[0.99,51.88],[0.991,500],[0.992,30.51]],"asks":[]}}
{"timestamp":1768863374056,"type":"book","data":{"type":"book","timestamp":1768863374056,"asset_id":"93658466248405584999260870388818827582402881579193486826612628010719686456341","market":"161587","bids":[],"asks":[[0.998,55000],[0.992,155],[0.99,27550],[0.989,155],[0.98,2100],[0.979,45],[0.976,15],[0.975,15],[0.974,15],[0.972,15],[0.95,200],[0.939,13.12],[0.92,255],[0.903,100],[0.901,100],[0.9,4000],[0.882,1397],[0.53,100],[0.51,100],[0.503,200],[0.501,100],[0.5,650],[0.25,60],[0.233,60],[0.231,60],[0.23,60],[0.01,51.88],[0.009,500],[0.008,30.51]]}}
{"timestamp":1768863374260,"type":"book","data":{"type":"book","timestamp":1768863374260,"asset_id":"24579524396187103736840535208642428472919490237386093648130273132471733218325","market":"161587","bids":[],"asks":[[0.999,99999],[0.998,55000],[0.992,155],[0.991,56055],[0.99,27095],[0.989,155],[0.98,2100],[0.97,300],[0.95,200],[0.92,255],[0.903,100],[0.902,10600],[0.901,100],[0.9,3500],[0.85,1312],[0.84,15],[0.83,15],[0.8,50],[0.78,15],[0.77,30],[0.76,15],[0.73,15],[0.72,1829],[0.71,15],[0.69,15],[0.67,30],[0.66,65],[0.53,100],[0.51,100],[0.503,200],[0.502,1500],[0.501,100],[0.5,250],[0.43,400],[0.25,60],[0.233,60],[0.232,352],[0.231,60],[0.23,60],[0.229,25],[0.228,6.27],[0.01,2670],[0.009,20632.57]]}}
{"timestamp":1768863374415,"type":"book","data":{"type":"book","timestamp":1768863374415,"asset_id":"114994275701207785626035089867908246328524209019060771004039661773577596682660","market":"161587","bids":[[0.001,99999],[0.002,55000],[0.008,155],[0.009,56055],[0.01,27095],[0.011,155],[0.02,2100],[0.03,300],[0.05,200],[0.08,255],[0.097,100],[0.098,10600],[0.099,100],[0.1,3500],[0.15,1312],[0.16,15],[0.17,15],[0.2,50],[0.22,15],[0.23,30],[0.24,15],[0.27,15],[0.28,1829],[0.29,15],[0.31,15],[0.33,30],[0.34,65],[0.47,100],[0.49,100],[0.497,200],[0.498,1500],[0.499,100],[0.5,250],[0.57,400],[0.75,60],[0.767,60],[0.768,352],[0.769,60],[0.77,60],[0.771,25],[0.772,6.27],[0.99,2670],[0.991,20632.57]],"asks":[]}}
{"timestamp":1768863374574,"type":"book","data":{"type":"book","timestamp":1768863374574,"asset_id":"84120862040579504625504822431671033934475567864159620983990020071323062262114","market":"161587","bids":[],"asks":[[0.999,99999],[0.998,55000],[0.992,155],[0.991,56055],[0.99,27247.54],[0.989,155],[0.98,2100],[0.97,300],[0.95,200],[0.94,5.4],[0.92,260.4],[0.903,100],[0.902,10500],[0.901,100],[0.9,3600],[0.86,50],[0.85,1262],[0.8,50],[0.73,50],[0.67,132.04],[0.66,65],[0.65,12.74],[0.64,30],[0.61,30],[0.53,100],[0.51,100],[0.503,200],[0.502,1500],[0.501,100],[0.5,650],[0.25,60],[0.233,60],[0.232,352],[0.231,60],[0.23,60],[0.229,25.41],[0.228,7.18],[0.01,25194.77],[0.009,704.54],[0.008,50.4],[0.007,45.31],[0.006,40.24],[0.005,35.17],[0.004,30.12],[0.003,25.07],[0.002,20.04],[0.001,24660.49]]}}
{"timestamp":1768863374776,"type":"book","data":{"type":"book","timestamp":1768863374776,"asset_id":"31605486503245302892484918796618037462252526786950870814089276799563620498223","market":"161587","bids":[[0.001,99999],[0.002,55000],[0.008,155],[0.009,56055],[0.01,27247.54],[0.011,155],[0.02,2100],[0.03,300],[0.05,200],[0.06,5.4],[0.08,260.4],[0.097,100],[0.098,10500],[0.099,100],[0.1,3600],[0.14,50],[0.15,1262],[0.2,50],[0.27,50],[0.33,132.04],[0.34,65],[0.35,12.74],[0.36,30],[0.39,30],[0.47,100],[0.49,100],[0.497,200],[0.498,1500],[0.499,100],[0.5,650],[0.75,60],[0.767,60],[0.768,352],[0.769,60],[0.77,60],[0.771,25.41],[0.772,7.18],[0.99,25194.77],[0.991,704.54],[0.992,50.4],[0.993,45.31],[0.994,40.24],[0.995,35.17],[0.996,30.12],[0.997,25.07],[0.998,20.04],[0.999,24660.49]],"asks":[]}}
{"timestamp":1768863374936,"type":"book","data":{"type":"book","timestamp":1768863374936,"asset_id":"52913956114341607252810840829851586741596208092031960365951091843918311115712","market":"161587","bids":[[0.001,11.47]],"asks":[[0.999,99999],[0.998,55000],[0.992,155],[0.991,56055],[0.99,27225],[0.989,155],[0.98,11000],[0.97,11400],[0.95,200],[0.92,255],[0.903,100],[0.902,10800],[0.901,100],[0.9,3630],[0.85,1162],[0.8,375],[0.73,50],[0.7,125],[0.66,50],[0.6,125],[0.53,100],[0.51,100],[0.503,200],[0.502,1500],[0.501,100],[0.5,650],[0.25,60],[0.233,60],[0.232,570],[0.231,60],[0.23,60],[0.229,25],[0.228,11.02],[0.01,10860],[0.009,704.54],[0.008,50.4],[0.007,10044.2],[0.006,40.24],[0.005,5032.02],[0.004,1461.53]]}}
{"timestamp":1768863375070,"type":"book","data":{"type":"book","timestamp":1768863375070,"asset_id":"101611788763604182009081598218650589988620418532960590031041926997259162552885","market":"161587","bids":[[0.001,99999],[0.002,55000],[0.008,155],[0.009,56055],[0.01,27225],[0.011,155],[0.02,11000],[0.03,11400],[0.05,200],[0.08,255],[0.097,100],[0.098,10800],[0.099,100],[0.1,3630],[0.15,1162],[0.2,375],[0.27,50],[0.3,125],[0.34,50],[0.4,125],[0.47,100],[0.49,100],[0.497,200],[0.498,1500],[0.499,100],[0.5,650],[0.75,60],[0.767,60],[0.768,570],[0.769,60],[0.77,60],[0.771,25],[0.772,11.02],[0.99,10860],[0.991,704.54],[0.992,50.4],[0.993,10044.2],[0.994,40.24],[0.995,5032.02],[0.996,1461.53]],"asks":[[0.999,11.47]]}}
{"timestamp":1768863375204,"type":"book","data":{"type":"book","timestamp":1768863375204,"asset_id":"60854482386705306074271452945147814262686505626338572994501795906620218532455","market":"161587","bids":[],"asks":[[0.999,99999],[0.998,55000],[0.992,155],[0.991,56055],[0.99,27050],[0.989,155],[0.98,1400],[0.95,1300],[0.92,155],[0.903,100],[0.902,10500],[0.901,100],[0.9,3600],[0.86,50],[0.859,1309],[0.53,100],[0.51,100],[0.503,200],[0.502,1500],[0.501,100],[0.5,650],[0.25,60],[0.233,60],[0.232,306],[0.231,60],[0.23,60],[0.229,5.51],[0.026,26.93],[0.025,25],[0.01,60],[0.009,704.54],[0.008,50.4],[0.007,45.31],[0.006,40.24],[0.005,35.17],[0.004,30.12],[0.003,25.07],[0.002,20.04],[0.001,5]]}}
{"timestamp":1768863375337,"type":"book","data":{"type":"book","timestamp":1768863375337,"asset_id":"109974464011407510311184872783466711205513981066359875513765218021885225826488","market":"161587","bids":[[0.001,99999],[0.002,55000],[0.008,155],[0.009,56055],[0.01,27050],[0.011,155],[0.02,1400],[0.05,1300],[0.08,155],[0.097,100],[0.098,10500],[0.099,100],[0.1,3600],[0.14,50],[0.141,1309],[0.47,100],[0.49,100],[0.497,200],[0.498,1500],[0.499,100],[0.5,650],[0.75,60],[0.767,60],[0.768,306],[0.769,60],[0.77,60],[0.771,5.51],[0.974,26.93],[0.975,25],[0.99,60],[0.991,704.54],[0.992,50.4],[0.993,45.31],[0.994,40.24],[0.995,35.17],[0.996,30.12],[0.997,25.07],[0.998,20.04],[0.999,5]],"asks":[]}}
{"timestamp":1768863375468,"type":"book","data":{"type":"book","timestamp":1768863375468,"asset_id":"55922024386758674305891505992525691291603317003989164672671598251586350466120","market":"161587","bids":[],"asks":[[0.999,99999],[0.998,55000],[0.992,155],[0.991,56055],[0.99,27225],[0.989,155],[0.98,2100],[0.97,300],[0.95,200],[0.92,255],[0.903,100],[0.902,10600],[0.901,100],[0.9,3500],[0.85,1312],[0.8,50],[0.73,50],[0.66,50],[0.6,1.29],[0.53,100],[0.51,100],[0.503,200],[0.502,1500],[0.501,100],[0.5,650],[0.25,60],[0.233,60],[0.231,60],[0.23,60],[0.229,53],[0.228,25.5],[0.227,11.02],[0.009,560.54],[0.008,50.4],[0.007,9862.51],[0.006,40.24],[0.005,5035.17],[0.004,1584.12],[0.003,25.07],[0.002,20.04]]}}
{"timestamp":1768863375618,"type":"book","data":{"type":"book","timestamp":1768863375618,"asset_id":"19801304860676403582225493665227711141504600330771746658898325407677304852268","market":"161587","bids":[[0.001,99999],[0.002,55000],[0.008,155],[0.009,56055],[0.01,27225],[0.011,155],[0.02,2100],[0.03,300],[0.05,200],[0.08,255],[0.097,100],[0.098,10600],[0.099,100],[0.1,3500],[0.15,1312],[0.2,50],[0.27,50],[0.34,50],[0.4,1.29],[0.47,100],[0.49,100],[0.497,200],[0.498,1500],[0.499,100],[0.5,650],[0.75,60],[0.767,60],[0.769,60],[0.77,60],[0.771,53],[0.772,25.5],[0.773,11.02],[0.991,560.54],[0.992,50.4],[0.993,9862.51],[0.994,40.24],[0.995,5035.17],[0.996,1584.12],[0.997,25.07],[0.998,20.04]],"asks":[]}}
{"timestamp":1768863375752,"type":"book","data":{"type":"book","timestamp":1768863375752,"asset_id":"48880380018017890900431761786115484907392010962335433452913978045838402624310","market":"161587","bids":[],"asks":[[0.999,99999],[0.998,55000],[0.992,155],[0.991,56055],[0.99,27080.5],[0.989,155],[0.98,1100],[0.97,300],[0.95,200],[0.92,255],[0.903,100],[0.902,10800],[0.901,100],[0.9,3500],[0.85,400],[0.84,2700],[0.68,100],[0.53,100],[0.51,100],[0.503,200],[0.502,1500],[0.501,100],[0.5,650],[0.25,60],[0.233,60],[0.232,570],[0.231,60],[0.23,60],[0.229,79.99],[0.228,5.51],[0.01,60],[0.009,570]]}}
{"timestamp":1768863375881,"type":"book","data":{"type":"book","timestamp":1768863375881,"asset_id":"109145261608975416082872682697463576130121579731407045593475179295471451760316","market":"161587","bids":[[0.001,99999],[0.002,55000],[0.008,155],[0.009,56055],[0.01,27080.5],[0.011,155],[0.02,1100],[0.03,300],[0.05,200],[0.08,255],[0.097,100],[0.098,10800],[0.099,100],[0.1,3500],[0.15,400],[0.16,2700],[0.32,100],[0.47,100],[0.49,100],[0.497,200],[0.498,1500],[0.499,100],[0.5,650],[0.75,60],[0.767,60],[0.768,570],[0.769,60],[0.77,60],[0.771,79.99],[0.772,5.51],[0.99,60],[0.991,570]],"asks":[]}}
{"timestamp":1768863376024,"type":"book","data":{"type":"book","timestamp":1768863376024,"asset_id":"83899814067708389406462136488758126712740448864742246697134907881561006435164","market":"161587","bids":[[0.001,104999],[0.002,55000],[0.008,155],[0.009,56055],[0.01,39824.96],[0.011,155],[0.02,13000],[0.03,11705],[0.04,350],[0.05,155],[0.06,1500],[0.07,1622],[0.08,155],[0.097,100],[0.098,10700],[0.099,100],[0.1,4905],[0.12,60],[0.15,400],[0.18,607],[0.2,1550],[0.25,68.96],[0.3,1300],[0.31,66],[0.36,6],[0.38,91.11],[0.39,12.67],[0.4,1307],[0.41,6],[0.43,100],[0.46,6],[0.47,115.21],[0.49,180.73],[0.497,200],[0.498,1500],[0.499,100],[0.5,404],[0.51,6],[0.52,300],[0.56,6],[0.6,31],[0.65,75],[0.68,398.84],[0.75,60],[0.76,10],[0.767,60],[0.769,60],[0.77,60],[0.8,70],[0.83,151],[0.88,25],[0.89,35.38],[0.93,14],[0.94,7650],[0.96,350],[0.99,4055.01],[0.991,704.54],[0.992,50.4],[0.993,45.31],[0.994,40.24],[0.995,35.17],[0.996,193.64],[0.997,25.07],[0.998,45.04],[0.999,1017006.32]],"asks":[]}}
{"timestamp":1768863376162,"type":"book","data":{"type":"book","timestamp":1768863376162,"asset_id":"73222854146421675752746898713600437350256675719760876211589957230651142068940","market":"161587","bids":[],"asks":[[0.999,104999],[0.998,55000],[0.992,155],[0.991,56055],[0.99,39824.96],[0.989,155],[0.98,13000],[0.97,11705],[0.96,350],[0.95,155],[0.94,1500],[0.93,1622],[0.92,155],[0.903,100],[0.902,10700],[0.901,100],[0.9,4905],[0.88,60],[0.85,400],[0.82,607],[0.8,1550],[0.75,68.96],[0.7,1300],[0.69,66],[0.64,6],[0.62,91.11],[0.61,12.67],[0.6,1307],[0.59,6],[0.57,100],[0.54,6],[0.53,115.21],[0.51,180.73],[0.503,200],[0.502,1500],[0.501,100],[0.5,404],[0.49,6],[0.48,300],[0.44,6],[0.4,31],[0.35,75],[0.32,398.84],[0.25,60],[0.24,10],[0.233,60],[0.231,60],[0.23,60],[0.2,70],[0.17,151],[0.12,25],[0.11,35.38],[0.07,14],[0.06,7650],[0.04,350],[0.01,4055.01],[0.009,704.54],[0.008,50.4],[0.007,45.31],[0.006,40.24],[0.005,35.17],[0.004,193.64],[0.003,25.07],[0.002,45.04],[0.001,1017006.32]]}}
{"timestamp":1768863376295,"type":"book","data":{"type":"book","timestamp":1768863376295,"asset_id":"81161860771407456912311120769878579619899929946299879214687327424218608547436","market":"161587","bids":[[0.001,99999],[0.002,55000],[0.008,155],[0.009,56055],[0.01,27085.5],[0.011,155],[0.02,405],[0.05,1300],[0.08,155],[0.097,100],[0.098,10600],[0.099,100],[0.1,3500],[0.15,1312],[0.2,50],[0.27,3.68],[0.28,1554],[0.34,50],[0.47,100],[0.49,100],[0.497,200],[0.498,1500],[0.499,100],[0.5,650],[0.75,60],[0.767,60],[0.769,60],[0.77,60],[0.771,5.51],[0.99,25258.99],[0.991,12638]],"asks":[]}}
{"timestamp":1768863376425,"type":"book","data":{"type":"book","timestamp":1768863376425,"asset_id":"25956482380991640813348808462637848560995942866526952689992175052729937091125","market":"161587","bids":[],"asks":[[0.999,99999],[0.998,55000],[0.992,155],[0.991,56055],[0.99,27085.5],[0.989,155],[0.98,405],[0.95,1300],[0.92,155],[0.903,100],[0.902,10600],[0.901,100],[0.9,3500],[0.85,1312],[0.8,50],[0.73,3.68],[0.72,1554],[0.66,50],[0.53,100],[0.51,100],[0.503,200],[0.502,1500],[0.501,100],[0.5,650],[0.25,60],[0.233,60],[0.231,60],[0.23,60],[0.229,5.51],[0.01,25258.99],[0.009,12638]]}}
{"timestamp":1768863376562,"type":"book","data":{"type":"book","timestamp":1768863376562,"asset_id":"44593029081753584788926889114013513766238403243363877426124190880950967120544","market":"161587","bids":[],"asks":[[0.999,99999],[0.998,55000],[0.992,155],[0.991,56055],[0.99,27090],[0.989,155],[0.98,11000],[0.97,11400],[0.95,200],[0.92,255],[0.903,100],[0.902,10800],[0.901,100],[0.9,3792],[0.85,1112],[0.8,287],[0.78,15],[0.77,50],[0.73,50],[0.72,1779],[0.7,287],[0.67,30],[0.66,50],[0.6,287],[0.53,100],[0.51,100],[0.503,200],[0.502,1500],[0.501,100],[0.5,650],[0.25,60],[0.24,13.11],[0.233,60],[0.232,351],[0.231,60],[0.23,184.36],[0.18,59.75],[0.1,72.51],[0.07,51.09],[0.069,25],[0.068,5.51],[0.01,3170.26],[0.009,30704.54],[0.008,50.4],[0.007,45.31],[0.006,40.24],[0.005,35.17],[0.004,30.12],[0.003,25.07],[0.002,20.04],[0.001,601.21]]}}
{"timestamp":1768863376717,"type":"book","data":{"type":"book","timestamp":1768863376717,"asset_id":"58170043872476553471723118954807775331301830716581845479265936031297794924283","market":"161587","bids":[[0.001,99999],[0.002,55000],[0.008,155],[0.009,56055],[0.01,27090],[0.011,155],[0.02,11000],[0.03,11400],[0.05,200],[0.08,255],[0.097,100],[0.098,10800],[0.099,100],[0.1,3792],[0.15,1112],[0.2,287],[0.22,15],[0.23,50],[0.27,50],[0.28,1779],[0.3,287],[0.33,30],[0.34,50],[0.4,287],[0.47,100],[0.49,100],[0.497,200],[0.498,1500],[0.499,100],[0.5,650],[0.75,60],[0.76,13.11],[0.767,60],[0.768,351],[0.769,60],[0.77,184.36],[0.82,59.75],[0.9,72.51],[0.93,51.09],[0.931,25],[0.932,5.51],[0.99,3170.26],[0.991,30704.54],[0.992,50.4],[0.993,45.31],[0.994,40.24],[0.995,35.17],[0.996,30.12],[0.997,25.07],[0.998,20.04],[0.999,601.21]],"asks":[]}}
{"timestamp":1768863376861,"type":"book","data":{"type":"book","timestamp":1768863376861,"asset_id":"79867546103527251186695916366803943551882905728089795572856469653182146573182","market":"161587","bids":[],"asks":[[0.99,7050],[0.98,21250],[0.92,55],[0.9,500],[0.89,25],[0.88,11.02]]}}
{"timestamp":1768863376997,"type":"book","data":{"type":"book","timestamp":1768863376997,"asset_id":"41178199935822859951659453545153667608689402220859633728390614617019943875191","market":"161587","bids":[[0.01,7050],[0.02,21250],[0.08,55],[0.1,500],[0.11,25],[0.12,11.02]],"asks":[]}}
{"timestamp":1768863377142,"type":"book","data":{"type":"book","timestamp":1768863377142,"asset_id":"53531231245646278389212793848294991664721833905088808710202491355873178178422","market":"161587","bids":[],"asks":[[0.998,55000],[0.992,155],[0.99,27550],[0.989,155],[0.98,2100],[0.95,200],[0.92,255],[0.903,100],[0.901,100],[0.9,4000],[0.89,1450],[0.53,100],[0.51,100],[0.503,200],[0.501,100],[0.25,60],[0.233,60],[0.231,60],[0.23,60],[0.229,25],[0.228,11.02],[0.01,35],[0.009,500]]}}
{"timestamp":1768863377269,"type":"book","data":{"type":"book","timestamp":1768863377269,"asset_id":"7142164331099478017237422095163785740435582452939850303622895577942265627947","market":"161587","bids":[[0.002,55000],[0.008,155],[0.01,27550],[0.011,155],[0.02,2100],[0.05,200],[0.08,255],[0.097,100],[0.099,100],[0.1,4000],[0.11,1450],[0.47,100],[0.49,100],[0.497,200],[0.499,100],[0.75,60],[0.767,60],[0.769,60],[0.77,60],[0.771,25],[0.772,11.02],[0.99,35],[0.991,500]],"asks":[]}}
{"timestamp":1768863377408,"type":"book","data":{"type":"book","timestamp":1768863377408,"asset_id":"94160515795879566153002944972741512251146074743459279119403075652615644127934","market":"161587","bids":[],"asks":[[0.999,99999],[0.998,55000],[0.992,155],[0.991,56055],[0.99,27115.5],[0.989,155],[0.98,1100],[0.97,300],[0.95,200],[0.92,255],[0.903,100],[0.902,10600],[0.901,100],[0.9,3500],[0.859,1359],[0.8,50],[0.73,50],[0.66,50],[0.53,100],[0.51,100],[0.503,200],[0.502,1500],[0.501,100],[0.5,400],[0.25,60],[0.233,60],[0.232,572],[0.231,60],[0.23,60],[0.229,53],[0.228,25.64],[0.01,22.96],[0.009,1671.54],[0.008,50.4],[0.007,45.31],[0.006,40.24],[0.005,35.17],[0.004,35.63],[0.003,25.07],[0.002,20.04],[0.001,1362.18]]}}
{"timestamp":1768863377582,"type":"book","data":{"type":"book","timestamp":1768863377582,"asset_id":"54255397860528834121594276849886749081550326493013665766978910049526974125093","market":"161587","bids":[[0.001,99999],[0.002,55000],[0.008,155],[0.009,56055],[0.01,27115.5],[0.011,155],[0.02,1100],[0.03,300],[0.05,200],[0.08,255],[0.097,100],[0.098,10600],[0.099,100],[0.1,3500],[0.141,1359],[0.2,50],[0.27,50],[0.34,50],[0.47,100],[0.49,100],[0.497,200],[0.498,1500],[0.499,100],[0.5,400],[0.75,60],[0.767,60],[0.768,572],[0.769,60],[0.77,60],[0.771,53],[0.772,25.64],[0.99,22.96],[0.991,1671.54],[0.992,50.4],[0.993,45.31],[0.994,40.24],[0.995,35.17],[0.996,35.63],[0.997,25.07],[0.998,20.04],[0.999,1362.18]],"asks":[]}}
{"timestamp":1768863377713,"type":"book","data":{"type":"book","timestamp":1768863377713,"asset_id":"2281309566574130642807730816726303714419168586997236681707499099398936474185","market":"161587","bids":[],"asks":[[0.999,99999],[0.998,55000],[0.992,155],[0.991,56055],[0.99,27080.5],[0.989,155],[0.98,400],[0.95,1300],[0.92,155],[0.903,100],[0.902,10800],[0.901,100],[0.9,3500],[0.85,400],[0.84,2700],[0.53,100],[0.51,100],[0.503,200],[0.502,1500],[0.501,100],[0.5,400],[0.25,60],[0.233,60],[0.232,439],[0.231,60],[0.23,60],[0.229,100],[0.228,11.02],[0.02,300],[0.019,144],[0.009,497.91]]}}
{"timestamp":1768863377858,"type":"book","data":{"type":"book","timestamp":1768863377858,"asset_id":"40425059971189106017414882636018632801130467619803319376400325238628202757805","market":"161587","bids":[[0.001,99999],[0.002,55000],[0.008,155],[0.009,56055],[0.01,27080.5],[0.011,155],[0.02,400],[0.05,1300],[0.08,155],[0.097,100],[0.098,10800],[0.099,100],[0.1,3500],[0.15,400],[0.16,2700],[0.47,100],[0.49,100],[0.497,200],[0.498,1500],[0.499,100],[0.5,400],[0.75,60],[0.767,60],[0.768,439],[0.769,60],[0.77,60],[0.771,100],[0.772,11.02],[0.98,300],[0.981,144],[0.991,497.91]],"asks":[]}}
{"timestamp":1768863377994,"type":"book","data":{"type":"book","timestamp":1768863377994,"asset_id":"85356151034142958812118326873548413742312509549787317293018964257573037506843","market":"161587","bids":[[0.001,14.99],[0.01,100],[0.04,62],[0.05,30],[0.051,25],[0.18,7.54]],"asks":[]}}
{"timestamp":1768863378133,"type":"book","data":{"type":"book","timestamp":1768863378133,"asset_id":"1338443871756370759655533003784332150179102079166042651190409012460654731030","market":"161587","bids":[],"asks":[[0.999,14.99],[0.99,100],[0.96,62],[0.95,30],[0.949,25],[0.82,7.54]]}}
{"timestamp":1768863378272,"type":"book","data":{"type":"book","timestamp":1768863378272,"asset_id":"104561417469280438624857704713303730213235315036975837304809065111097458149113","market":"161587","bids":[],"asks":[[0.999,99999],[0.998,55000],[0.992,155],[0.991,56055],[0.99,27000],[0.989,155],[0.98,2100],[0.97,300],[0.95,200],[0.92,255],[0.903,100],[0.902,10700],[0.901,100],[0.9,3650],[0.86,50],[0.85,400],[0.846,649],[0.8,50],[0.73,50],[0.66,50],[0.53,100],[0.51,100],[0.503,200],[0.502,1500],[0.501,100],[0.25,60],[0.233,60],[0.232,571],[0.231,60],[0.23,60],[0.176,26.33],[0.174,16.53],[0.173,25],[0.172,11.02],[0.01,2000],[0.009,704.54],[0.008,50.4],[0.007,45.31],[0.006,40.24],[0.005,35.17],[0.004,30.12],[0.003,25.07],[0.002,20.04],[0.001,5]]}}
{"timestamp":1768863378408,"type":"book","data":{"type":"book","timestamp":1768863378408,"asset_id":"90508786464936430054960174057014699141737305916344517232838682389750156463791","market":"161587","bids":[[0.001,99999],[0.002,55000],[0.008,155],[0.009,56055],[0.01,27000],[0.011,155],[0.02,2100],[0.03,300],[0.05,200],[0.08,255],[0.097,100],[0.098,10700],[0.099,100],[0.1,3650],[0.14,50],[0.15,400],[0.154,649],[0.2,50],[0.27,50],[0.34,50],[0.47,100],[0.49,100],[0.497,200],[0.498,1500],[0.499,100],[0.75,60],[0.767,60],[0.768,571],[0.769,60],[0.77,60],[0.824,26.33],[0.826,16.53],[0.827,25],[0.828,11.02],[0.99,2000],[0.991,704.54],[0.992,50.4],[0.993,45.31],[0.994,40.24],[0.995,35.17],[0.996,30.12],[0.997,25.07],[0.998,20.04],[0.999,5]],"asks":[]}}
{"timestamp":1768863378600,"type":"book","data":{"type":"book","timestamp":1768863378600,"asset_id":"51640950844529073540440468921446646609840378218681177771835773486695222195363","market":"161587","bids":[],"asks":[[0.999,99999],[0.998,55000],[0.992,155],[0.991,56055],[0.99,27050],[0.989,155],[0.98,2100],[0.97,300],[0.95,200],[0.92,255],[0.903,100],[0.902,10700],[0.901,100],[0.9,3650],[0.86,50],[0.85,400],[0.849,662],[0.8,50],[0.73,50],[0.66,50],[0.53,100],[0.51,100],[0.503,200],[0.502,1500],[0.501,100],[0.25,60],[0.233,60],[0.231,60],[0.23,60],[0.229,47.68],[0.228,5.51],[0.01,2060],[0.009,704.54],[0.008,50.4],[0.007,45.31],[0.006,40.24],[0.005,35.17],[0.004,30.12],[0.003,25.07],[0.002,20.04],[0.001,5]]}}
{"timestamp":1768863378727,"type":"book","data":{"type":"book","timestamp":1768863378727,"asset_id":"45580499855571815703798438949570518410899588907349508423148937057071386680821","market":"161587","bids":[[0.001,99999],[0.002,55000],[0.008,155],[0.009,56055],[0.01,27050],[0.011,155],[0.02,2100],[0.03,300],[0.05,200],[0.08,255],[0.097,100],[0.098,10700],[0.099,100],[0.1,3650],[0.14,50],[0.15,400],[0.151,662],[0.2,50],[0.27,50],[0.34,50],[0.47,100],[0.49,100],[0.497,200],[0.498,1500],[0.499,100],[0.75,60],[0.767,60],[0.769,60],[0.77,60],[0.771,47.68],[0.772,5.51],[0.99,2060],[0.991,704.54],[0.992,50.4],[0.993,45.31],[0.994,40.24],[0.995,35.17],[0.996,30.12],[0.997,25.07],[0.998,20.04],[0.999,5]],"asks":[]}}
{"timestamp":1768863378870,"type":"book","data":{"type":"book","timestamp":1768863378870,"asset_id":"80955465573788561519287799238070819726068512211014816914447962346674298193040","market":"161587","bids":[[0.001,99999],[0.002,55000],[0.008,155],[0.009,56055],[0.01,27000],[0.011,155],[0.02,1400],[0.05,1300],[0.08,155],[0.097,100],[0.098,10700],[0.099,100],[0.1,3650],[0.14,50],[0.15,400],[0.151,662],[0.2,50],[0.27,50],[0.34,50],[0.47,100],[0.49,100],[0.497,200],[0.498,1500],[0.499,100],[0.75,60],[0.767,60],[0.768,572],[0.769,60],[0.77,60],[0.772,41.57],[0.773,25],[0.99,11908.49],[0.991,704.54],[0.992,50.4],[0.993,45.31],[0.994,40.24],[0.995,35.17],[0.996,30.12],[0.997,25.07],[0.998,20.04],[0.999,907.07]],"asks":[]}}
{"timestamp":1768863379004,"type":"book","data":{"type":"book","timestamp":1768863379004,"asset_id":"113421581696345614187888921984273009220039924345606711784540408098901651166996","market":"161587","bids":[],"asks":[[0.999,99999],[0.998,55000],[0.992,155],[0.991,56055],[0.99,27000],[0.989,155],[0.98,1400],[0.95,1300],[0.92,155],[0.903,100],[0.902,10700],[0.901,100],[0.9,3650],[0.86,50],[0.85,400],[0.8,50],[0.73,50],[0.66,50],[0.53,100],[0.51,100],[0.503,200],[0.502,1500],[0.501,100],[0.25,60],[0.233,60],[0.232,572],[0.231,60],[0.23,60],[0.228,41.57],[0.227,25],[0.01,11908.49],[0.009,704.54],[0.008,50.4],[0.007,45.31],[0.006,40.24],[0.005,35.17],[0.004,30.12],[0.003,25.07],[0.002,20.04],[0.001,907.07]]}}
{"timestamp":1768863379158,"type":"book","data":{"type":"book","timestamp":1768863379158,"asset_id":"49404837919351069799222213313406510058029700415636380320303383151853211606461","market":"161587","bids":[[0.002,55000],[0.008,155],[0.01,27550],[0.011,155],[0.02,2100],[0.03,16],[0.04,25],[0.05,230],[0.08,255],[0.097,100],[0.099,100],[0.1,4100],[0.15,500],[0.47,100],[0.49,100],[0.497,200],[0.499,100],[0.75,60],[0.767,60],[0.769,60],[0.77,60],[0.771,25],[0.772,5.51],[0.99,629.12],[0.991,500]],"asks":[]}}
{"timestamp":1768863379294,"type":"book","data":{"type":"book","timestamp":1768863379294,"asset_id":"3986689974687749401569762749790970504891242225395088232355646709432459801755","market":"161587","bids":[],"asks":[[0.998,55000],[0.992,155],[0.99,27550],[0.989,155],[0.98,2100],[0.97,16],[0.96,25],[0.95,230],[0.92,255],[0.903,100],[0.901,100],[0.9,4100],[0.85,500],[0.53,100],[0.51,100],[0.503,200],[0.501,100],[0.25,60],[0.233,60],[0.231,60],[0.23,60],[0.229,25],[0.228,5.51],[0.01,629.12],[0.009,500]]}}
{"timestamp":1768863379441,"type":"book","data":{"type":"book","timestamp":1768863379441,"asset_id":"99168974266843179978354052234653670711404329776440032034213602407634856160915","market":"161587","bids":[],"asks":[[0.998,55000],[0.992,155],[0.99,27550],[0.989,155],[0.98,2100],[0.95,200],[0.92,255],[0.903,100],[0.901,100],[0.9,4000],[0.88,550],[0.53,100],[0.51,100],[0.503,200],[0.501,100],[0.25,60],[0.233,60],[0.231,60],[0.23,60],[0.009,500]]}}
{"timestamp":1768863379583,"type":"book","data":{"type":"book","timestamp":1768863379583,"asset_id":"15990901704723151577745665847245503498242174471602590883916296397653362695840","market":"161587","bids":[[0.002,55000],[0.008,155],[0.01,27550],[0.011,155],[0.02,2100],[0.05,200],[0.08,255],[0.097,100],[0.099,100],[0.1,4000],[0.12,550],[0.47,100],[0.49,100],[0.497,200],[0.499,100],[0.75,60],[0.767,60],[0.769,60],[0.77,60],[0.991,500]],"asks":[]}}
{"timestamp":1768863379738,"type":"book","data":{"type":"book","timestamp":1768863379738,"asset_id":"23117719725712472213764522342988165288233183423538400617261626518241093294703","market":"161587","bids":[],"asks":[[0.99,7050],[0.92,55],[0.9,500],[0.89,25],[0.88,5.51]]}}
{"timestamp":1768863379930,"type":"book","data":{"type":"book","timestamp":1768863379930,"asset_id":"29048920123422896108922056005135610136327701403093628618323034011331962504239","market":"161587","bids":[[0.01,7050],[0.08,55],[0.1,500],[0.11,25],[0.12,5.51]],"asks":[]}}
{"timestamp":1768863380068,"type":"book","data":{"type":"book","timestamp":1768863380068,"asset_id":"89196817534650214518343470810012288381453951103093009932230380153906165978759","market":"161587","bids":[[0.002,55000],[0.008,155],[0.01,27550],[0.011,155],[0.02,2100],[0.05,200],[0.08,255],[0.097,100],[0.099,100],[0.1,4200],[0.146,75.61],[0.15,400],[0.47,100],[0.49,100],[0.497,200],[0.499,100],[0.75,60],[0.767,60],[0.769,60],[0.77,60],[0.99,6.28],[0.991,500],[0.992,25],[0.993,5.51]],"asks":[]}}
{"timestamp":1768863380211,"type":"book","data":{"type":"book","timestamp":1768863380211,"asset_id":"15633387036100115266322094291506265989553265793281973176905404845199622381518","market":"161587","bids":[],"asks":[[0.998,55000],[0.992,155],[0.99,27550],[0.989,155],[0.98,2100],[0.95,200],[0.92,255],[0.903,100],[0.901,100],[0.9,4200],[0.854,75.61],[0.85,400],[0.53,100],[0.51,100],[0.503,200],[0.501,100],[0.25,60],[0.233,60],[0.231,60],[0.23,60],[0.01,6.28],[0.009,500],[0.008,25],[0.007,5.51]]}}
{"timestamp":1768863380339,"type":"book","data":{"type":"book","timestamp":1768863380339,"asset_id":"49335016365941641409952976129113215306810130872796911770220968674695550227620","market":"161587","bids":[[0.001,14.99],[0.01,50],[0.95,20],[0.979,24.36],[0.98,25],[0.981,5.51]],"asks":[]}}
{"timestamp":1768863380469,"type":"book","data":{"type":"book","timestamp":1768863380469,"asset_id":"83762004711915891788797964319803421904923212191800334283779459846638388049876","market":"161587","bids":[],"asks":[[0.999,14.99],[0.99,50],[0.05,20],[0.021,24.36],[0.02,25],[0.019,5.51]]}}
{"timestamp":1768863380606,"type":"book","data":{"type":"book","timestamp":1768863380606,"asset_id":"51859461336493165622472425900220749386708018986520817300834494664041845827840","market":"161587","bids":[],"asks":[[0.998,55000],[0.992,155],[0.99,27565],[0.989,155],[0.98,2100],[0.95,200],[0.92,255],[0.903,100],[0.901,100],[0.9,4000],[0.87,550],[0.53,100],[0.51,100],[0.503,200],[0.501,100],[0.25,60],[0.233,60],[0.231,60],[0.23,60],[0.224,16.53],[0.223,50],[0.01,35],[0.009,500]]}}
{"timestamp":1768863380740,"type":"book","data":{"type":"book","timestamp":1768863380740,"asset_id":"8529817399593092932868619955036462122236499040969175261261611684243758201892","market":"161587","bids":[[0.002,55000],[0.008,155],[0.01,27565],[0.011,155],[0.02,2100],[0.05,200],[0.08,255],[0.097,100],[0.099,100],[0.1,4000],[0.13,550],[0.47,100],[0.49,100],[0.497,200],[0.499,100],[0.75,60],[0.767,60],[0.769,60],[0.77,60],[0.776,16.53],[0.777,50],[0.99,35],[0.991,500]],"asks":[]}}
{"timestamp":1768863380875,"type":"book","data":{"type":"book","timestamp":1768863380875,"asset_id":"9120915729602249445620577692804945151875704171399581054915760950889830582597","market":"161587","bids":[[0.002,55000],[0.008,155],[0.01,27550],[0.011,155],[0.02,2100],[0.03,33],[0.05,200],[0.08,255],[0.097,100],[0.099,100],[0.1,4000],[0.118,550],[0.47,100],[0.49,100],[0.497,200],[0.499,100],[0.5,400],[0.75,60],[0.767,60],[0.769,60],[0.77,60],[0.99,95],[0.991,500],[0.992,30.99]],"asks":[]}}
{"timestamp":1768863381012,"type":"book","data":{"type":"book","timestamp":1768863381012,"asset_id":"47977653821762789883975001802056017674308731879435373641510409955848058610918","market":"161587","bids":[],"asks":[[0.998,55000],[0.992,155],[0.99,27550],[0.989,155],[0.98,2100],[0.97,33],[0.95,200],[0.92,255],[0.903,100],[0.901,100],[0.9,4000],[0.882,550],[0.53,100],[0.51,100],[0.503,200],[0.501,100],[0.5,400],[0.25,60],[0.233,60],[0.231,60],[0.23,60],[0.01,95],[0.009,500],[0.008,30.99]]}}
{"timestamp":1768863381152,"type":"book","data":{"type":"book","timestamp":1768863381152,"asset_id":"81039110590188118185318140412490382472467200844540360650605775700109662880113","market":"161587","bids":[[0.002,55000],[0.008,155],[0.01,27550],[0.011,155],[0.02,2100],[0.05,200],[0.08,255],[0.097,100],[0.099,100],[0.1,4000],[0.118,550],[0.213,19.36],[0.214,56.25],[0.47,100],[0.49,100],[0.497,200],[0.499,100],[0.75,60],[0.767,60],[0.769,60],[0.77,60],[0.771,25],[0.99,70],[0.991,500],[0.992,10.51]],"asks":[]}}
{"timestamp":1768863381287,"type":"book","data":{"type":"book","timestamp":1768863381287,"asset_id":"2667309821146099214315983821785431182474285484243878097986007057468677343348","market":"161587","bids":[],"asks":[[0.998,55000],[0.992,155],[0.99,27550],[0.989,155],[0.98,2100],[0.95,200],[0.92,255],[0.903,100],[0.901,100],[0.9,4000],[0.882,550],[0.787,19.36],[0.786,56.25],[0.53,100],[0.51,100],[0.503,200],[0.501,100],[0.5,650],[0.25,60],[0.233,60],[0.231,60],[0.23,60],[0.229,25],[0.01,70],[0.009,500],[0.008,10.51]]}}
{"timestamp":1768863381445,"type":"book","data":{"type":"book","timestamp":1768863381445,"asset_id":"24149837465812544749905902967180296948686555674306251030277465520781639999133","market":"161587","bids":[],"asks":[[0.99,150]]}}
{"timestamp":1768863381579,"type":"book","data":{"type":"book","timestamp":1768863381579,"asset_id":"84384442381949376194512910399545184963727099278155579224374632446057025235247","market":"161587","bids":[[0.01,150]],"asks":[]}}
{"timestamp":1768863381714,"type":"book","data":{"type":"book","timestamp":1768863381714,"asset_id":"34130029555333481410138913504371238679856860292518927586466769475661539617443","market":"161587","bids":[],"asks":[[0.998,55000],[0.992,155],[0.99,27550],[0.989,155],[0.98,2100],[0.95,200],[0.92,255],[0.903,100],[0.901,100],[0.9,4000],[0.87,550],[0.53,100],[0.51,100],[0.503,200],[0.501,100],[0.5,650],[0.25,60],[0.233,60],[0.231,60],[0.23,60],[0.229,25],[0.228,5.51],[0.01,35],[0.009,500]]}}
{"timestamp":1768863381845,"type":"book","data":{"type":"book","timestamp":1768863381845,"asset_id":"79608484467359140021508230970847311886652283787528822345528181281312803620924","market":"161587","bids":[[0.002,55000],[0.008,155],[0.01,27550],[0.011,155],[0.02,2100],[0.05,200],[0.08,255],[0.097,100],[0.099,100],[0.1,4000],[0.13,550],[0.47,100],[0.49,100],[0.497,200],[0.499,100],[0.5,650],[0.75,60],[0.767,60],[0.769,60],[0.77,60],[0.771,25],[0.772,5.51],[0.99,35],[0.991,500]],"asks":[]}}
{"timestamp":1768863381983,"type":"book","data":{"type":"book","timestamp":1768863381983,"asset_id":"97040212064446394960539836623423876178691598622568810188407885534471977571669","market":"161587","bids":[],"asks":[[0.999,99999],[0.998,55000],[0.992,155],[0.991,56055],[0.99,27115.5],[0.989,155],[0.97,400],[0.95,1300],[0.92,155],[0.903,100],[0.902,10600],[0.901,100],[0.9,3500],[0.85,650],[0.8,50],[0.73,50],[0.66,50],[0.53,100],[0.51,100],[0.503,200],[0.502,1500],[0.501,100],[0.5,650],[0.25,60],[0.233,60],[0.232,922],[0.231,60],[0.23,60],[0.229,25],[0.18,10.52],[0.07,6.19],[0.069,5.51],[0.01,60],[0.009,613.54],[0.008,50.4],[0.007,10045.31],[0.006,1372.24],[0.005,35.17],[0.004,30.12],[0.003,25.07],[0.002,20.04],[0.001,0.99]]}}
{"timestamp":1768863382128,"type":"book","data":{"type":"book","timestamp":1768863382128,"asset_id":"66861719874868483654276583920179307623815372003867226773517436334945195054581","market":"161587","bids":[[0.001,99999],[0.002,55000],[0.008,155],[0.009,56055],[0.01,27115.5],[0.011,155],[0.03,400],[0.05,1300],[0.08,155],[0.097,100],[0.098,10600],[0.099,100],[0.1,3500],[0.15,650],[0.2,50],[0.27,50],[0.34,50],[0.47,100],[0.49,100],[0.497,200],[0.498,1500],[0.499,100],[0.5,650],[0.75,60],[0.767,60],[0.768,922],[0.769,60],[0.77,60],[0.771,25],[0.82,10.52],[0.93,6.19],[0.931,5.51],[0.99,60],[0.991,613.54],[0.992,50.4],[0.993,10045.31],[0.994,1372.24],[0.995,35.17],[0.996,30.12],[0.997,25.07],[0.998,20.04],[0.999,0.99]],"asks":[]}}
{"timestamp":1768863382796,"type":"book","data":{"type":"book","timestamp":1768863382796,"asset_id":"84384442381949376194512910399545184963727099278155579224374632446057025235247","market":"0xa080927f19a54d86c89bd3555541b3abfbf53e98cf0e5f964e1729528e7df2d6","bids":[[0.01,150]],"asks":[],"hash":"6d6390000b07ee85acf3555c6d22a9896c55fccf"}}
{"timestamp":1768863382797,"type":"book","data":{"type":"book","timestamp":1768863382797,"asset_id":"49404837919351069799222213313406510058029700415636380320303383151853211606461","market":"0x649872b98f3cd5c94d604030777b871d0ef6256d6c9485eef4dfd32c8e550870","bids":[[0.002,55000],[0.008,155],[0.01,27550],[0.011,155],[0.02,2100],[0.03,16],[0.04,25],[0.05,230],[0.08,255],[0.097,100],[0.099,100],[0.1,4100],[0.15,500],[0.47,100],[0.49,100],[0.497,200],[0.499,100],[0.5,650],[0.75,60],[0.767,60],[0.769,60],[0.77,60],[0.771,25],[0.772,5.51],[0.99,629.12],[0.991,500]],"asks":[],"hash":"a4d2f4f6668b8288cc458554179f2e378d1c6738"}}
{"timestamp":1768863382797,"type":"book","data":{"type":"book","timestamp":1768863382797,"asset_id":"81039110590188118185318140412490382472467200844540360650605775700109662880113","market":"0xed49b308e6f28a527f10ce2c9d849a45f515935c1adc95a111893399c1709299","bids":[[0.002,55000],[0.008,155],[0.01,27550],[0.011,155],[0.02,2100],[0.05,200],[0.08,255],[0.097,100],[0.099,100],[0.1,4000],[0.118,550],[0.213,19.36],[0.214,56.25],[0.47,100],[0.49,100],[0.497,200],[0.499,100],[0.5,650],[0.75,60],[0.767,60],[0.769,60],[0.77,60],[0.771,25],[0.99,70],[0.991,500],[0.992,10.51]],"asks":[],"hash":"270d415a3bdf20851312453d8a9d811ac50b20f4"}}
{"timestamp":1768863382797,"type":"book","data":{"type":"book","timestamp":1768863382797,"asset_id":"113025031494916309150086220666714068684066916056870600664866463237320949012683","market":"0x19d9dc9b734a8270440da3511c0127c64e18e7c034656dba600c67e1f671eec8","bids":[[0.002,55000],[0.008,155],[0.01,27550],[0.011,155],[0.02,2100],[0.05,200],[0.08,255],[0.097,100],[0.099,100],[0.1,4000],[0.141,1259],[0.47,100],[0.49,100],[0.497,200],[0.499,100],[0.5,250],[0.55,427.36],[0.75,60],[0.767,60],[0.769,60],[0.77,60],[0.771,25],[0.772,5.51],[0.99,69.49],[0.991,500]],"asks":[],"hash":"c0898efd9cbb1294f8677ce2b6c9ae3584506a15"}}
{"timestamp":1768863382797,"type":"book","data":{"type":"book","timestamp":1768863382797,"asset_id":"41178199935822859951659453545153667608689402220859633728390614617019943875191","market":"0x3530777a6c3e8eb380a4eb72fdaa7c15381797a758a692d6d325bba4db4994d6","bids":[[0.01,7050],[0.03,10832],[0.08,55],[0.1,500],[0.11,25],[0.12,11.02]],"asks":[],"hash":"9bf929b8b2b55c7a3ef9728fb80def3b75f3041f"}}
{"timestamp":1768863382797,"type":"book","data":{"type":"book","timestamp":1768863382797,"asset_id":"31795349211219422607185815612973220690717749068121740516256733008230250593184","market":"0xd95cae1f78c63f65c14098d643ada7421731ec63e24fcb99628d9e5362e7ac61","bids":[],"asks":[[0.998,55000],[0.992,155],[0.99,27550],[0.989,155],[0.98,2100],[0.95,200],[0.92,255],[0.903,100],[0.901,100],[0.9,4000],[0.863,20],[0.859,1259],[0.53,100],[0.51,100],[0.503,200],[0.501,100],[0.5,650],[0.25,60],[0.233,60],[0.231,60],[0.23,60],[0.229,25],[0.01,35],[0.009,500],[0.008,10.51]],"hash":"935af4e6ffdaead5ca95fc42fa320c3ab1457496"}}
{"timestamp":1768863382797,"type":"book","data":{"type":"book","timestamp":1768863382797,"asset_id":"24085294160146023460801270886062008540816580162480837570482544017068711307043","market":"0xe32de27f7e7e4bb886b7063180e29f7acc6d9cc8d09e8bffbffad7b835628aeb","bids":[],"asks":[[0.998,55000],[0.992,155],[0.99,27550],[0.989,155],[0.98,2100],[0.95,200],[0.92,255],[0.903,100],[0.901,100],[0.9,4000],[0.89,1450],[0.53,100],[0.51,100],[0.503,200],[0.501,100],[0.5,650],[0.25,60],[0.233,60],[0.231,60],[0.23,60],[0.229,25],[0.228,11.02],[0.01,35],[0.009,500]],"hash":"85887c32f0fd4bb75c02732e721872d7c95c38c9"}}
{"timestamp":1768863382797,"type":"book","data":{"type":"book","timestamp":1768863382797,"asset_id":"71775041801808637972785922632852978725572532275252146056957073487383515608173","market":"0x2723a2fc360d2c29d15b6ee7904688deead72c9970cbee5112880d532b73574d","bids":[],"asks":[[0.99,50],[0.98,30.51]],"hash":"54a0a51f966e1bc2fcf9b6f8bcf8bf2cac40e029"}}
{"timestamp":1768863382798,"type":"book","data":{"type":"book","timestamp":1768863382798,"asset_id":"38249703376174183440478117641561819852912686676086886922395617711410224047669","market":"0x366ea8dd3a7f8672384fcd74ddbb3001a7798ce9d32fb08e6bf8c538c7e6798f","bids":[[0.002,55000],[0.008,155],[0.01,27550],[0.011,155],[0.02,2100],[0.05,200],[0.08,255],[0.097,100],[0.099,100],[0.1,4000],[0.118,1397],[0.372,17.15],[0.47,100],[0.49,100],[0.497,200],[0.499,100],[0.5,650],[0.75,60],[0.767,60],[0.769,60],[0.77,60],[0.771,25],[0.99,95],[0.991,500],[0.992,5.51]],"asks":[],"hash":"9a2e916b65c96eba4ab12a045b62fadcc2ecc345"}}
{"timestamp":1768863382798,"type":"book","data":{"type":"book","timestamp":1768863382798,"asset_id":"84120862040579504625504822431671033934475567864159620983990020071323062262114","market":"0x6092c3e3f04adbe787e53a3d6d9356ce6dba625ac96d017b396a574b34d7a8a4","bids":[],"asks":[[0.999,99999],[0.998,55000],[0.992,155],[0.991,56055],[0.99,27247.54],[0.989,155],[0.98,2100],[0.97,300],[0.95,200],[0.94,5.4],[0.92,260.4],[0.903,100],[0.902,10500],[0.901,100],[0.9,3600],[0.86,50],[0.85,600],[0.8,50],[0.73,50],[0.67,132.04],[0.66,65],[0.65,12.74],[0.64,30],[0.61,30],[0.53,100],[0.51,100],[0.503,200],[0.502,1500],[0.501,100],[0.5,650],[0.25,60],[0.233,60],[0.232,352],[0.231,60],[0.23,60],[0.229,25.41],[0.228,7.18],[0.01,25194.77],[0.009,704.54],[0.008,50.4],[0.007,45.31],[0.006,40.24],[0.005,35.17],[0.004,30.12],[0.003,25.07],[0.002,20.04],[0.001,24660.49]],"hash":"8f8d1427f25ee757a50e3ca23e59c42a6404d0ff"}}
{"timestamp":1768863382798,"type":"book","data":{"type":"book","timestamp":1768863382798,"asset_id":"54255397860528834121594276849886749081550326493013665766978910049526974125093","market":"0x07d3174d7e1b4b22ad3109744e9768dc255e2fe8749cc25cfc8cc900b1d3c62e","bids":[[0.001,99999],[0.002,55000],[0.008,155],[0.009,56055],[0.01,27115.5],[0.011,155],[0.02,1100],[0.03,300],[0.05,200],[0.08,255],[0.097,100],[0.098,10600],[0.099,100],[0.1,3500],[0.141,1359],[0.2,50],[0.27,50],[0.34,50],[0.47,100],[0.49,100],[0.497,200],[0.498,1500],[0.499,100],[0.5,650],[0.75,60],[0.767,60],[0.768,572],[0.769,60],[0.77,60],[0.771,53],[0.772,25.64],[0.99,22.96],[0.991,1671.54],[0.992,50.4],[0.993,45.31],[0.994,40.24],[0.995,35.17],[0.996,35.63],[0.997,25.07],[0.998,20.04],[0.999,1362.18]],"asks":[],"hash":"8894c93063b6e0be5072e23ca7aba9af04381bcd"}}
{"timestamp":1768863382798,"type":"book","data":{"type":"book","timestamp":1768863382798,"asset_id":"83899814067708389406462136488758126712740448864742246697134907881561006435164","market":"0x1d9921b0a498d2f0f68351a35d4b5e5fd6b34f5800e2b0dc304fe82872fff15b","bids":[[0.001,104999],[0.002,55000],[0.008,155],[0.009,56055],[0.01,39824.96],[0.011,155],[0.02,13000],[0.03,11705],[0.04,350],[0.05,155],[0.06,1500],[0.07,1622],[0.08,155],[0.097,100],[0.098,10700],[0.099,100],[0.1,4905],[0.12,60],[0.15,400],[0.18,55],[0.2,1550],[0.25,68.96],[0.3,1300],[0.31,66],[0.36,6],[0.38,91.11],[0.39,12.67],[0.4,1307],[0.41,6],[0.43,100],[0.46,6],[0.47,115.21],[0.49,180.73],[0.497,200],[0.498,1500],[0.499,100],[0.5,404],[0.51,6],[0.52,300],[0.56,6],[0.6,31],[0.65,75],[0.68,398.84],[0.75,60],[0.76,10],[0.767,60],[0.769,60],[0.77,60],[0.8,70],[0.83,151],[0.88,25],[0.89,35.38],[0.93,14],[0.94,7650],[0.96,350],[0.99,4055.01],[0.991,704.54],[0.992,50.4],[0.993,45.31],[0.994,40.24],[0.995,35.17],[0.996,193.64],[0.997,25.07],[0.998,45.04],[0.999,1017006.32]],"asks":[],"hash":"d71a90e21daa6ccf7a79ee387eb900bda35daad0"}}
{"timestamp":1768863382798,"type":"book","data":{"type":"book","timestamp":1768863382798,"asset_id":"98888987637702944200466394029062132161347270306418627034681906287677121368389","market":"0x29067ebc925c8bb2d14f0bb8c7946005e51538109dc2e4d201639a40232bc93c","bids":[],"asks":[[0.998,55000],[0.992,155],[0.99,27550],[0.989,155],[0.98,2100],[0.95,200],[0.92,255],[0.903,100],[0.901,100],[0.9,4000],[0.882,1397],[0.53,100],[0.51,100],[0.503,200],[0.501,100],[0.5,650],[0.25,60],[0.233,60],[0.231,60],[0.23,60],[0.01,95],[0.009,500],[0.008,30.51]],"hash":"ccb6b73aacda169a355f90e47b796cd7b59ae13d"}}
{"timestamp":1768863382798,"type":"book","data":{"type":"book","timestamp":1768863382798,"asset_id":"43577718766112357875300730326646730119346466279136183595509365799679832624641","market":"0x676d078b81497e987ad19344ca4e3569f89b4e659f91a545f8e9690d6dfa4b39","bids":[],"asks":[[0.999,14.99],[0.99,29594],[0.989,9090],[0.55,74.99],[0.549,30.51]],"hash":"ad7a3a0ccd0e5f4b791e5a36300ca64419cf2a85"}}
{"timestamp":1768863382798,"type":"book","data":{"type":"book","timestamp":1768863382798,"asset_id":"71459940788768289369388827341933628291041428032682324236872093006027462842932","market":"0xc3bb03827ffd54c915712e01268060664edc4b9a7e10c3687a46414a8fbd61fa","bids":[[0.002,55000],[0.008,155],[0.01,27550],[0.011,155],[0.02,2100],[0.05,200],[0.08,255],[0.097,100],[0.099,100],[0.1,4000],[0.118,1397],[0.47,100],[0.475,75.62],[0.49,100],[0.497,200],[0.499,100],[0.5,650],[0.75,60],[0.767,60],[0.769,60],[0.77,60],[0.771,25],[0.99,95],[0.991,500],[0.992,10.51]],"asks":[],"hash":"f5ae917829affacd0c2b48281412addc72e03072"}}
{"timestamp":1768863382799,"type":"book","data":{"type":"book","timestamp":1768863382799,"asset_id":"49637045107561300232921209964038170407460446885617809869047360275570604727981","market":"0x366ea8dd3a7f8672384fcd74ddbb3001a7798ce9d32fb08e6bf8c538c7e6798f","bids":[],"asks":[[0.998,55000],[0.992,155],[0.99,27550],[0.989,155],[0.98,2100],[0.95,200],[0.92,255],[0.903,100],[0.901,100],[0.9,4000],[0.882,1397],[0.628,17.15],[0.53,100],[0.51,100],[0.503,200],[0.501,100],[0.5,650],[0.25,60],[0.233,60],[0.231,60],[0.23,60],[0.229,25],[0.01,95],[0.009,500],[0.008,5.51]],"hash":"7b3851ade0db58c21424607a206fc4abace57e40"}}
{"timestamp":1768863382799,"type":"book","data":{"type":"book","timestamp":1768863382799,"asset_id":"31605486503245302892484918796618037462252526786950870814089276799563620498223","market":"0x6092c3e3f04adbe787e53a3d6d9356ce6dba625ac96d017b396a574b34d7a8a4","bids":[[0.001,99999],[0.002,55000],[0.008,155],[0.009,56055],[0.01,27247.54],[0.011,155],[0.02,2100],[0.03,300],[0.05,200],[0.06,5.4],[0.08,260.4],[0.097,100],[0.098,10500],[0.099,100],[0.1,3600],[0.14,50],[0.15,600],[0.2,50],[0.27,50],[0.33,132.04],[0.34,65],[0.35,12.74],[0.36,30],[0.39,30],[0.47,100],[0.49,100],[0.497,200],[0.498,1500],[0.499,100],[0.5,650],[0.75,60],[0.767,60],[0.768,352],[0.769,60],[0.77,60],[0.771,25.41],[0.772,7.18],[0.99,25194.77],[0.991,704.54],[0.992,50.4],[0.993,45.31],[0.994,40.24],[0.995,35.17],[0.996,30.12],[0.997,25.07],[0.998,20.04],[0.999,24660.49]],"asks":[],"hash":"023076883dbc902989776170dae61b32a7a73778"}}
{"timestamp":1768863382799,"type":"book","data":{"type":"book","timestamp":1768863382799,"asset_id":"99168974266843179978354052234653670711404329776440032034213602407634856160915","market":"0x62f8a610f290315f0054814a9ffda8d29b311c03bf2812775383a909dc369957","bids":[],"asks":[[0.998,55000],[0.992,155],[0.99,27550],[0.989,155],[0.98,2100],[0.95,200],[0.92,255],[0.903,100],[0.901,100],[0.9,4000],[0.88,550],[0.53,100],[0.51,100],[0.503,200],[0.501,100],[0.5,650],[0.25,60],[0.233,60],[0.231,60],[0.23,60],[0.009,500]],"hash":"ee21f2f9e33c18fbc9460a7799bdd9e1a696ecbb"}}
{"timestamp":1768863382799,"type":"book","data":{"type":"book","timestamp":1768863382799,"asset_id":"89196817534650214518343470810012288381453951103093009932230380153906165978759","market":"0x5b588025b5d3cf45804912af31eb2a07577931c00213aba7c23c6e3ad3931672","bids":[[0.002,55000],[0.008,155],[0.01,27550],[0.011,155],[0.02,2100],[0.05,200],[0.08,255],[0.097,100],[0.099,100],[0.1,4100],[0.146,75.61],[0.15,400],[0.47,100],[0.49,100],[0.497,200],[0.499,100],[0.5,650],[0.75,60],[0.767,60],[0.769,60],[0.77,60],[0.99,6.28],[0.991,500],[0.992,25],[0.993,5.51]],"asks":[],"hash":"5510a2a7ad14d4380091d3f266b52a9598d159d6"}}
{"timestamp":1768863382799,"type":"book","data":{"type":"book","timestamp":1768863382799,"asset_id":"34367065238487927523900111259648857646009474251375713435120986499501795995070","market":"0x4fb109511c3ba4c5bda3fe81940240b56523fbdfedd5d4f0b024af169b8ea047","bids":[],"asks":[[0.998,55000],[0.992,155],[0.99,27550],[0.989,155],[0.98,2100],[0.95,200],[0.92,255],[0.903,100],[0.901,100],[0.9,4000],[0.89,1450],[0.53,100],[0.51,100],[0.503,200],[0.501,100],[0.5,650],[0.25,60],[0.233,60],[0.231,60],[0.23,60],[0.009,500],[0.008,55.51]],"hash":"297d71c3b8dedfe1e8703b304ef73bda69f4bc2a"}}
{"timestamp":1768863382799,"type":"book","data":{"type":"book","timestamp":1768863382799,"asset_id":"111436004474608829181688199751793007557865850840578909060278133660760146801937","market":"0xca03f1e4e2a81ed9d91331e4354e4f07fd1f897dd400f41f810d6db09e8b7a83","bids":[],"asks":[[0.998,55000],[0.992,155],[0.99,27550],[0.989,155],[0.98,2100],[0.95,200],[0.92,255],[0.903,100],[0.901,100],[0.9,4000],[0.882,1397],[0.53,100],[0.51,100],[0.503,200],[0.501,100],[0.5,650],[0.25,60],[0.233,60],[0.231,60],[0.23,60],[0.01,95],[0.009,500],[0.008,30.51]],"hash":"09309cbb2313d92246cabcbdf2294aefd664f561"}}
{"timestamp":1768863382799,"type":"book","data":{"type":"book","timestamp":1768863382799,"asset_id":"83762004711915891788797964319803421904923212191800334283779459846638388049876","market":"0xa8e21d98ce3635fdafa916aa404f8dfd4eb941ec5a36e54b07f9fef1dcfa9051","bids":[],"asks":[[0.999,14.99],[0.99,50],[0.05,20],[0.021,24.36],[0.02,25],[0.019,5.51]],"hash":"84cc79b61b25ac8aca8511cdc062e7dd6819d219"}}
{"timestamp":1768863382799,"type":"book","data":{"type":"book","timestamp":1768863382799,"asset_id":"51859461336493165622472425900220749386708018986520817300834494664041845827840","market":"0xab8df169971e779e7a5c7867fafa15340113bcebc1c2b6f4714c17f20b4c7868","bids":[],"asks":[[0.998,55000],[0.992,155],[0.99,27565],[0.989,155],[0.98,2100],[0.95,200],[0.92,255],[0.903,100],[0.901,100],[0.9,4000],[0.87,1313],[0.53,100],[0.51,100],[0.503,200],[0.501,100],[0.5,650],[0.25,60],[0.233,60],[0.231,60],[0.23,60],[0.221,50],[0.22,16.53],[0.01,35],[0.009,500]],"hash":"d953ff6ea8335e781fa6d2524281a80b2d3ef9bc"}}
{"timestamp":1768863382799,"type":"book","data":{"type":"book","timestamp":1768863382799,"asset_id":"1338443871756370759655533003784332150179102079166042651190409012460654731030","market":"0x2bf2d7f54a03b4b01cff5a9e010a7fa7c0532f40f111cc19050c4b7499794f87","bids":[],"asks":[[0.999,14.99],[0.99,100],[0.96,62],[0.95,30],[0.949,25],[0.82,7.54]],"hash":"88ec3ae06467777b071b42bed6f46d0c311ce686"}}
{"timestamp":1768863382800,"type":"book","data":{"type":"book","timestamp":1768863382800,"asset_id":"55922024386758674305891505992525691291603317003989164672671598251586350466120","market":"0x1a77154d564015025f6711d1d26945c1df621f15affb41f0e919f455e417c63b","bids":[],"asks":[[0.999,99999],[0.998,55000],[0.992,155],[0.991,56055],[0.99,27225],[0.989,155],[0.98,2100],[0.97,300],[0.95,200],[0.92,255],[0.903,100],[0.902,10600],[0.901,100],[0.9,3500],[0.85,650],[0.8,50],[0.73,50],[0.66,50],[0.6,1.29],[0.53,100],[0.51,100],[0.503,200],[0.502,1500],[0.501,100],[0.5,650],[0.25,60],[0.233,60],[0.231,60],[0.23,60],[0.229,53],[0.228,25.5],[0.227,11.02],[0.009,560.54],[0.008,50.4],[0.007,9862.51],[0.006,40.24],[0.005,5035.17],[0.004,1584.12],[0.003,25.07],[0.002,20.04]],"hash":"f4a4ff6132eb01207fb682596c11f425f34dc98d"}}
{"timestamp":1768863382800,"type":"book","data":{"type":"book","timestamp":1768863382800,"asset_id":"53531231245646278389212793848294991664721833905088808710202491355873178178422","market":"0xb4cc3add2f2934d7ed77672faa5f0607f52b6e01921e6c5698142d5f21eb219b","bids":[],"asks":[[0.998,55000],[0.992,155],[0.99,27550],[0.989,155],[0.98,2100],[0.95,200],[0.92,255],[0.903,100],[0.901,100],[0.9,4000],[0.89,550],[0.53,100],[0.51,100],[0.503,200],[0.501,100],[0.5,650],[0.25,60],[0.233,60],[0.231,60],[0.23,60],[0.229,25],[0.228,11.02],[0.01,35],[0.009,500]],"hash":"897ca9531c77d5bcb67d33b3c4ddf9c8ae5b3c2a"}}
{"timestamp":1768863382800,"type":"book","data":{"type":"book","timestamp":1768863382800,"asset_id":"19801304860676403582225493665227711141504600330771746658898325407677304852268","market":"0x1a77154d564015025f6711d1d26945c1df621f15affb41f0e919f455e417c63b","bids":[[0.001,99999],[0.002,55000],[0.008,155],[0.009,56055],[0.01,27225],[0.011,155],[0.02,2100],[0.03,300],[0.05,200],[0.08,255],[0.097,100],[0.098,10600],[0.099,100],[0.1,3500],[0.15,650],[0.2,50],[0.27,50],[0.34,50],[0.4,1.29],[0.47,100],[0.49,100],[0.497,200],[0.498,1500],[0.499,100],[0.5,650],[0.75,60],[0.767,60],[0.769,60],[0.77,60],[0.771,53],[0.772,25.5],[0.773,11.02],[0.991,560.54],[0.992,50.4],[0.993,9862.51],[0.994,40.24],[0.995,5035.17],[0.996,1584.12],[0.997,25.07],[0.998,20.04]],"asks":[],"hash":"39d52cd0166876e4066c69d7e21546f0ff3d8c19"}}
{"timestamp":1768863382800,"type":"book","data":{"type":"book","timestamp":1768863382800,"asset_id":"15633387036100115266322094291506265989553265793281973176905404845199622381518","market":"0x5b588025b5d3cf45804912af31eb2a07577931c00213aba7c23c6e3ad3931672","bids":[],"asks":[[0.998,55000],[0.992,155],[0.99,27550],[0.989,155],[0.98,2100],[0.95,200],[0.92,255],[0.903,100],[0.901,100],[0.9,4100],[0.854,75.61],[0.85,400],[0.53,100],[0.51,100],[0.503,200],[0.501,100],[0.5,650],[0.25,60],[0.233,60],[0.231,60],[0.23,60],[0.01,6.28],[0.009,500],[0.008,25],[0.007,5.51]],"hash":"c0c33396c98234a14bf5af15411b185240023909"}}
{"timestamp":1768863382800,"type":"book","data":{"type":"book","timestamp":1768863382800,"asset_id":"114994275701207785626035089867908246328524209019060771004039661773577596682660","market":"0xc7def456adf8952db9672f973dcf89ca06106ec530bb462efb9b7c2fbb84ddbd","bids":[[0.001,99999],[0.002,55000],[0.008,155],[0.009,56055],[0.01,27095],[0.011,155],[0.02,2100],[0.03,300],[0.05,200],[0.08,255],[0.097,100],[0.098,10600],[0.099,100],[0.1,3500],[0.15,650],[0.16,15],[0.17,15],[0.2,50],[0.22,15],[0.23,30],[0.24,15],[0.27,15],[0.28,1829],[0.29,15],[0.31,15],[0.33,30],[0.34,65],[0.47,100],[0.49,100],[0.497,200],[0.498,1500],[0.499,100],[0.5,250],[0.57,400],[0.75,60],[0.767,60],[0.768,352],[0.769,60],[0.77,60],[0.771,25],[0.772,6.27],[0.99,2670],[0.991,20632.57]],"asks":[],"hash":"d73013ab7c5f65f93e843bd9a4d478a8e6f84562"}}
{"timestamp":1768863382800,"type":"book","data":{"type":"book","timestamp":1768863382800,"asset_id":"45580499855571815703798438949570518410899588907349508423148937057071386680821","market":"0xbe7dc7ab76f592bc89d6c6c606e28d119cb90dd503bd543c61d79d8c2cb18d0d","bids":[[0.001,99999],[0.002,55000],[0.008,155],[0.009,56055],[0.01,27050],[0.011,155],[0.02,2100],[0.03,300],[0.05,200],[0.08,255],[0.097,100],[0.098,10700],[0.099,100],[0.1,3650],[0.14,50],[0.15,400],[0.151,662],[0.2,50],[0.27,50],[0.34,50],[0.47,100],[0.49,100],[0.497,200],[0.498,1500],[0.499,100],[0.5,650],[0.75,60],[0.767,60],[0.769,60],[0.77,60],[0.771,47.68],[0.772,5.51],[0.99,2060],[0.991,704.54],[0.992,50.4],[0.993,45.31],[0.994,40.24],[0.995,35.17],[0.996,30.12],[0.997,25.07],[0.998,20.04],[0.999,5]],"asks":[],"hash":"0abdd17472c2c61a3fe5a212346af069266d1bbe"}}
{"timestamp":1768863382800,"type":"book","data":{"type":"book","timestamp":1768863382800,"asset_id":"102470506234631856714287226623345182033813197411154001523556742367360332249186","market":"0xd95cae1f78c63f65c14098d643ada7421731ec63e24fcb99628d9e5362e7ac61","bids":[[0.002,55000],[0.008,155],[0.01,27550],[0.011,155],[0.02,2100],[0.05,200],[0.08,255],[0.097,100],[0.099,100],[0.1,4000],[0.137,20],[0.141,1259],[0.47,100],[0.49,100],[0.497,200],[0.499,100],[0.5,650],[0.75,60],[0.767,60],[0.769,60],[0.77,60],[0.771,25],[0.99,35],[0.991,500],[0.992,10.51]],"asks":[],"hash":"84844033ce6d63a63e5d3a62d7a1ed0704d9b62c"}}
{"timestamp":1768863382800,"type":"book","data":{"type":"book","timestamp":1768863382800,"asset_id":"66861719874868483654276583920179307623815372003867226773517436334945195054581","market":"0x4288c9795de3151e756e44062d7772b2767e5a6d213dea0a116d1317729a5e1a","bids":[[0.001,99999],[0.002,55000],[0.008,155],[0.009,56055],[0.01,27115.5],[0.011,155],[0.03,400],[0.05,1300],[0.08,155],[0.097,100],[0.098,10600],[0.099,100],[0.1,3500],[0.15,1312],[0.2,50],[0.27,50],[0.34,50],[0.47,100],[0.49,100],[0.497,200],[0.498,1500],[0.499,100],[0.5,650],[0.75,60],[0.767,60],[0.768,922],[0.769,60],[0.77,60],[0.771,25],[0.82,10.52],[0.93,6.19],[0.931,5.51],[0.99,60],[0.991,613.54],[0.992,50.4],[0.993,10045.31],[0.994,1372.24],[0.995,35.17],[0.996,30.12],[0.997,25.07],[0.998,20.04],[0.999,0.99]],"asks":[],"hash":"2401926db04777ca8724aeb2f8c439123f69083d"}}
{"timestamp":1768863382800,"type":"book","data":{"type":"book","timestamp":1768863382800,"asset_id":"109145261608975416082872682697463576130121579731407045593475179295471451760316","market":"0x9f5498adae626b37f869b924cc5a599eda5a11da525059b1404f89f8713c51c6","bids":[[0.001,99999],[0.002,55000],[0.008,155],[0.009,56055],[0.01,27080.5],[0.011,155],[0.02,1100],[0.03,300],[0.05,200],[0.08,255],[0.097,100],[0.098,10800],[0.099,100],[0.1,3500],[0.15,400],[0.16,2079],[0.32,100],[0.47,100],[0.49,100],[0.497,200],[0.498,1500],[0.499,100],[0.5,650],[0.75,60],[0.767,60],[0.768,570],[0.769,60],[0.77,60],[0.771,79.99],[0.772,5.51],[0.99,60],[0.991,570]],"asks":[],"hash":"0070e3066eb8821312e440548da98318b0d70f6c"}}
{"timestamp":1768863382801,"type":"book","data":{"type":"book","timestamp":1768863382801,"asset_id":"79608484467359140021508230970847311886652283787528822345528181281312803620924","market":"0xe0c45c38597364a10040b4cd5b6b68e099fa0f67a7cf906b7fda8acbc981b382","bids":[[0.002,55000],[0.008,155],[0.01,27550],[0.011,155],[0.02,2100],[0.05,200],[0.08,255],[0.097,100],[0.099,100],[0.1,4000],[0.13,1313],[0.47,100],[0.49,100],[0.497,200],[0.499,100],[0.5,650],[0.75,60],[0.767,60],[0.769,60],[0.77,60],[0.771,25],[0.772,5.51],[0.99,35],[0.991,500]],"asks":[],"hash":"d7d55622139112fc3e5238fcb4f697774dd0e022"}}
{"timestamp":1768863382801,"type":"book","data":{"type":"book","timestamp":1768863382801,"asset_id":"94285110769567966486463661297410356109827983764157167229272297139989795256953","market":"0x4fb109511c3ba4c5bda3fe81940240b56523fbdfedd5d4f0b024af169b8ea047","bids":[[0.002,55000],[0.008,155],[0.01,27550],[0.011,155],[0.02,2100],[0.05,200],[0.08,255],[0.097,100],[0.099,100],[0.1,4000],[0.11,1450],[0.47,100],[0.49,100],[0.497,200],[0.499,100],[0.5,650],[0.75,60],[0.767,60],[0.769,60],[0.77,60],[0.991,500],[0.992,55.51]],"asks":[],"hash":"0e471d513938ac31e7c6df1968241fbc147aa742"}}
{"timestamp":1768863382801,"type":"book","data":{"type":"book","timestamp":1768863382801,"asset_id":"7142164331099478017237422095163785740435582452939850303622895577942265627947","market":"0xb4cc3add2f2934d7ed77672faa5f0607f52b6e01921e6c5698142d5f21eb219b","bids":[[0.002,55000],[0.008,155],[0.01,27550],[0.011,155],[0.02,2100],[0.05,200],[0.08,255],[0.097,100],[0.099,100],[0.1,4000],[0.11,550],[0.47,100],[0.49,100],[0.497,200],[0.499,100],[0.5,650],[0.75,60],[0.767,60],[0.769,60],[0.77,60],[0.771,25],[0.772,11.02],[0.99,35],[0.991,500]],"asks":[],"hash":"c4830756e2b8224b71cb3da96d491d23afa5f948"}}
{"timestamp":1768863382801,"type":"book","data":{"type":"book","timestamp":1768863382801,"asset_id":"81161860771407456912311120769878579619899929946299879214687327424218608547436","market":"0x2397d58005858b5b7271c776adac1b4fa32491286339f3dc3139df9dece7d6c3","bids":[[0.001,99999],[0.002,55000],[0.008,155],[0.009,56055],[0.01,27085.5],[0.011,155],[0.02,405],[0.05,1300],[0.08,155],[0.097,100],[0.098,10600],[0.099,100],[0.1,3500],[0.15,650],[0.2,50],[0.27,3.68],[0.28,1554],[0.34,50],[0.47,100],[0.49,100],[0.497,200],[0.498,1500],[0.499,100],[0.5,650],[0.75,60],[0.767,60],[0.769,60],[0.77,60],[0.771,5.51],[0.99,25258.99],[0.991,12638]],"asks":[],"hash":"72eabff8568542f3da278e1f747c438f2b209dc9"}}
{"timestamp":1768863382801,"type":"book","data":{"type":"book","timestamp":1768863382801,"asset_id":"47977653821762789883975001802056017674308731879435373641510409955848058610918","market":"0x0a60f9a74cecb46233fd113a9b77d3aeeacbb57a7d44d78423225ef7e2e81a71","bids":[],"asks":[[0.998,55000],[0.992,155],[0.99,27550],[0.989,155],[0.98,2100],[0.97,33],[0.95,200],[0.92,255],[0.903,100],[0.901,100],[0.9,4000],[0.882,550],[0.53,100],[0.51,100],[0.503,200],[0.501,100],[0.5,650],[0.25,60],[0.233,60],[0.231,60],[0.23,60],[0.01,95],[0.009,500],[0.008,30.99]],"hash":"ee94af92e6efeab370c0a83f89f17f32b06034af"}}
{"timestamp":1768863382801,"type":"book","data":{"type":"book","timestamp":1768863382801,"asset_id":"9120915729602249445620577692804945151875704171399581054915760950889830582597","market":"0x0a60f9a74cecb46233fd113a9b77d3aeeacbb57a7d44d78423225ef7e2e81a71","bids":[[0.002,55000],[0.008,155],[0.01,27550],[0.011,155],[0.02,2100],[0.03,33],[0.05,200],[0.08,255],[0.097,100],[0.099,100],[0.1,4000],[0.118,550],[0.47,100],[0.49,100],[0.497,200],[0.499,100],[0.5,650],[0.75,60],[0.767,60],[0.769,60],[0.77,60],[0.99,95],[0.991,500],[0.992,30.99]],"asks":[],"hash":"2700455e7b854ec9b10a7ecd6a14c1c4e4c8632c"}}
{"timestamp":1768863382801,"type":"book","data":{"type":"book","timestamp":1768863382801,"asset_id":"9031636498902109489531840330955202379047865759768140186724288939684833165378","market":"0x676d078b81497e987ad19344ca4e3569f89b4e659f91a545f8e9690d6dfa4b39","bids":[[0.001,14.99],[0.01,29594],[0.011,9090],[0.45,74.99],[0.451,30.51]],"asks":[],"hash":"325d2438765859f6e533d9dfe5ae83e0ac843727"}}
{"timestamp":1768863382801,"type":"book","data":{"type":"book","timestamp":1768863382801,"asset_id":"2667309821146099214315983821785431182474285484243878097986007057468677343348","market":"0xed49b308e6f28a527f10ce2c9d849a45f515935c1adc95a111893399c1709299","bids":[],"asks":[[0.998,55000],[0.992,155],[0.99,27550],[0.989,155],[0.98,2100],[0.95,200],[0.92,255],[0.903,100],[0.901,100],[0.9,4000],[0.882,550],[0.787,19.36],[0.786,56.25],[0.53,100],[0.51,100],[0.503,200],[0.501,100],[0.5,650],[0.25,60],[0.233,60],[0.231,60],[0.23,60],[0.229,25],[0.01,70],[0.009,500],[0.008,10.51]],"hash":"79b8d0b9c07b4f918c5b9b097031af418d663e68"}}
{"timestamp":1768863382801,"type":"book","data":{"type":"book","timestamp":1768863382801,"asset_id":"51640950844529073540440468921446646609840378218681177771835773486695222195363","market":"0xbe7dc7ab76f592bc89d6c6c606e28d119cb90dd503bd543c61d79d8c2cb18d0d","bids":[],"asks":[[0.999,99999],[0.998,55000],[0.992,155],[0.991,56055],[0.99,27050],[0.989,155],[0.98,2100],[0.97,300],[0.95,200],[0.92,255],[0.903,100],[0.902,10700],[0.901,100],[0.9,3650],[0.86,50],[0.85,400],[0.849,662],[0.8,50],[0.73,50],[0.66,50],[0.53,100],[0.51,100],[0.503,200],[0.502,1500],[0.501,100],[0.5,650],[0.25,60],[0.233,60],[0.231,60],[0.23,60],[0.229,47.68],[0.228,5.51],[0.01,2060],[0.009,704.54],[0.008,50.4],[0.007,45.31],[0.006,40.24],[0.005,35.17],[0.004,30.12],[0.003,25.07],[0.002,20.04],[0.001,5]],"hash":"6eaeef6be766645a6c0a56d1ac8bea0b1e49ec8e"}}
{"timestamp":1768863382801,"type":"book","data":{"type":"book","timestamp":1768863382801,"asset_id":"23117719725712472213764522342988165288233183423538400617261626518241093294703","market":"0x6964f9a8a358b91d5a0a13458445986bc803779225de647a0b9f0caff8f8aa04","bids":[],"asks":[[0.99,7050],[0.97,10832],[0.92,55],[0.9,500],[0.89,25],[0.88,5.51]],"hash":"e271f9a1754e7c8ba7ddfc805a7851765cc026d3"}}
{"timestamp":1768863382801,"type":"book","data":{"type":"book","timestamp":1768863382801,"asset_id":"40425059971189106017414882636018632801130467619803319376400325238628202757805","market":"0x6dfb3d43cd0029526113cdd085d4ebab3fc9274d3095295d69ac24e27ab1dd98","bids":[[0.001,99999],[0.002,55000],[0.008,155],[0.009,56055],[0.01,27080.5],[0.011,155],[0.02,400],[0.05,1300],[0.08,155],[0.097,100],[0.098,10800],[0.099,100],[0.1,3500],[0.15,400],[0.16,2700],[0.47,100],[0.49,100],[0.497,200],[0.498,1500],[0.499,100],[0.5,650],[0.75,60],[0.767,60],[0.768,439],[0.769,60],[0.77,60],[0.771,100],[0.772,11.02],[0.98,300],[0.981,144],[0.991,497.91]],"asks":[],"hash":"5d08e058f654d6237a34adf16115d7703e4d95da"}}
{"timestamp":1768863382801,"type":"book","data":{"type":"book","timestamp":1768863382801,"asset_id":"79867546103527251186695916366803943551882905728089795572856469653182146573182","market":"0x3530777a6c3e8eb380a4eb72fdaa7c15381797a758a692d6d325bba4db4994d6","bids":[],"asks":[[0.99,7050],[0.97,10832],[0.92,55],[0.9,500],[0.89,25],[0.88,11.02]],"hash":"c37fd9987de197b5ab350143c65aecedd038fad0"}}
{"timestamp":1768863382802,"type":"book","data":{"type":"book","timestamp":1768863382802,"asset_id":"15990901704723151577745665847245503498242174471602590883916296397653362695840","market":"0x62f8a610f290315f0054814a9ffda8d29b311c03bf2812775383a909dc369957","bids":[[0.002,55000],[0.008,155],[0.01,27550],[0.011,155],[0.02,2100],[0.05,200],[0.08,255],[0.097,100],[0.099,100],[0.1,4000],[0.12,550],[0.47,100],[0.49,100],[0.497,200],[0.499,100],[0.5,650],[0.75,60],[0.767,60],[0.769,60],[0.77,60],[0.991,500]],"asks":[],"hash":"910ecf8862a0a661c83469d46d03a188b5a759c8"}}
{"timestamp":1768863382802,"type":"book","data":{"type":"book","timestamp":1768863382802,"asset_id":"68660619242068838780359514667334675625428574513507330730861992120392412078977","market":"0xe32de27f7e7e4bb886b7063180e29f7acc6d9cc8d09e8bffbffad7b835628aeb","bids":[[0.002,55000],[0.008,155],[0.01,27550],[0.011,155],[0.02,2100],[0.05,200],[0.08,255],[0.097,100],[0.099,100],[0.1,4000],[0.11,1450],[0.47,100],[0.49,100],[0.497,200],[0.499,100],[0.5,650],[0.75,60],[0.767,60],[0.769,60],[0.77,60],[0.771,25],[0.772,11.02],[0.99,35],[0.991,500]],"asks":[],"hash":"c927790983d745cef4d743dcedf4d169ec261e97"}}
{"timestamp":1768863382802,"type":"book","data":{"type":"book","timestamp":1768863382802,"asset_id":"33672246756272849240665557330388834060801478981449620394497796903940273756329","market":"0x2723a2fc360d2c29d15b6ee7904688deead72c9970cbee5112880d532b73574d","bids":[[0.01,50],[0.02,30.51]],"asks":[],"hash":"e53563cfbc42beaceffa9086a7b9c0065f492161"}}
{"timestamp":1768863382802,"type":"book","data":{"type":"book","timestamp":1768863382802,"asset_id":"52913956114341607252810840829851586741596208092031960365951091843918311115712","market":"0xd86b1c9ac7abe2f2260bccff1c73b2b5aaa8bd72c764d232f9b8a5cbf632e04f","bids":[[0.001,11.47]],"asks":[[0.999,99999],[0.998,55000],[0.992,155],[0.991,56055],[0.99,27225],[0.989,155],[0.98,11000],[0.97,11400],[0.95,200],[0.92,255],[0.903,100],[0.902,10800],[0.901,100],[0.9,3630],[0.85,1162],[0.8,375],[0.73,50],[0.7,125],[0.66,50],[0.6,125],[0.53,100],[0.51,100],[0.503,200],[0.502,1500],[0.501,100],[0.5,650],[0.25,60],[0.233,60],[0.232,570],[0.231,60],[0.23,60],[0.229,25],[0.228,11.02],[0.01,10860],[0.009,704.54],[0.008,50.4],[0.007,10044.2],[0.006,40.24],[0.005,5032.02],[0.004,1461.53]],"hash":"1b68a3b79942d6f33c410a9c21ec6a1d5808e24a"}}
{"timestamp":1768863382802,"type":"book","data":{"type":"book","timestamp":1768863382802,"asset_id":"65238912540593149767509870878968239590124887893827161207600259653260563923070","market":"0x1371096e2c0565a907fc829678011b2f494ba2bcc4d2fa7e34463ce2b507f203","bids":[],"asks":[[0.99,50],[0.98,30.51]],"hash":"9d7c094451d1c8d4be920e7a20f64027141fde65"}}
{"timestamp":1768863382802,"type":"book","data":{"type":"book","timestamp":1768863382802,"asset_id":"74774623971709706821569763625609154232615320360891965400140251966412790258500","market":"0x994852b813326db703afc598ac97f4baec56a0e9da0e586d9a0154f8b146df28","bids":[],"asks":[[0.99,7050],[0.98,5000],[0.92,55],[0.9,500],[0.89,2954],[0.76,30.29],[0.72,37.5],[0.71,25]],"hash":"52c4fd12d7bef5398777415a417364bf655034f4"}}
{"timestamp":1768863382802,"type":"book","data":{"type":"book","timestamp":1768863382802,"asset_id":"52706147105070524363009267529922604376781175933531786990678540409860700140950","market":"0x1371096e2c0565a907fc829678011b2f494ba2bcc4d2fa7e34463ce2b507f203","bids":[[0.01,50],[0.02,30.51]],"asks":[],"hash":"a9a12e8e178199be04189069457aa7088cfd2269"}}
{"timestamp":1768863382802,"type":"book","data":{"type":"book","timestamp":1768863382802,"asset_id":"101611788763604182009081598218650589988620418532960590031041926997259162552885","market":"0xd86b1c9ac7abe2f2260bccff1c73b2b5aaa8bd72c764d232f9b8a5cbf632e04f","bids":[[0.001,99999],[0.002,55000],[0.008,155],[0.009,56055],[0.01,27225],[0.011,155],[0.02,11000],[0.03,11400],[0.05,200],[0.08,255],[0.097,100],[0.098,10800],[0.099,100],[0.1,3630],[0.15,1162],[0.2,375],[0.27,50],[0.3,125],[0.34,50],[0.4,125],[0.47,100],[0.49,100],[0.497,200],[0.498,1500],[0.499,100],[0.5,650],[0.75,60],[0.767,60],[0.768,570],[0.769,60],[0.77,60],[0.771,25],[0.772,11.02],[0.99,10860],[0.991,704.54],[0.992,50.4],[0.993,10044.2],[0.994,40.24],[0.995,5032.02],[0.996,1461.53]],"asks":[[0.999,11.47]],"hash":"9f13d02dd3775c23710a7487441c61da7cfa45b6"}}
{"timestamp":1768863382802,"type":"book","data":{"type":"book","timestamp":1768863382802,"asset_id":"90508786464936430054960174057014699141737305916344517232838682389750156463791","market":"0x74359b1889c9b4f5a84c1cac8cfd2dd6f48731fedb44f7a7e803b9c8cd6de6d8","bids":[[0.001,99999],[0.002,55000],[0.008,155],[0.009,56055],[0.01,27000],[0.011,155],[0.02,2100],[0.03,300],[0.05,200],[0.08,255],[0.097,100],[0.098,10700],[0.099,100],[0.1,3650],[0.14,50],[0.15,400],[0.151,662],[0.2,50],[0.27,50],[0.34,50],[0.47,100],[0.49,100],[0.497,200],[0.498,1500],[0.499,100],[0.5,650],[0.75,60],[0.767,60],[0.768,571],[0.769,60],[0.77,60],[0.824,26.33],[0.826,16.53],[0.827,25],[0.828,11.02],[0.99,2000],[0.991,704.54],[0.992,50.4],[0.993,45.31],[0.994,40.24],[0.995,35.17],[0.996,30.12],[0.997,25.07],[0.998,20.04],[0.999,5]],"asks":[],"hash":"5dd4da928e2e71ec255c2ff3ed1a7b8ff80f0087"}}
{"timestamp":1768863382802,"type":"book","data":{"type":"book","timestamp":1768863382802,"asset_id":"43563596164617197569984035984240875096743987893839105155156535794052660412514","market":"0xca03f1e4e2a81ed9d91331e4354e4f07fd1f897dd400f41f810d6db09e8b7a83","bids":[[0.002,55000],[0.008,155],[0.01,27550],[0.011,155],[0.02,2100],[0.05,200],[0.08,255],[0.097,100],[0.099,100],[0.1,4000],[0.118,1397],[0.47,100],[0.49,100],[0.497,200],[0.499,100],[0.5,650],[0.75,60],[0.767,60],[0.769,60],[0.77,60],[0.99,95],[0.991,500],[0.992,30.51]],"asks":[],"hash":"9a5daf50fb4486f7ced65f161018b0ff5b76649e"}}
{"timestamp":1768863382802,"type":"book","data":{"type":"book","timestamp":1768863382802,"asset_id":"113421581696345614187888921984273009220039924345606711784540408098901651166996","market":"0x8884313775cb4f37d3de3fa1e9afc797d9d0fb72cae523fbfa7853fab179d500","bids":[],"asks":[[0.999,99999],[0.998,55000],[0.992,155],[0.991,56055],[0.99,27000],[0.989,155],[0.98,1400],[0.95,1300],[0.92,155],[0.903,100],[0.902,10700],[0.901,100],[0.9,3650],[0.86,50],[0.85,400],[0.8,50],[0.73,50],[0.66,50],[0.53,100],[0.51,100],[0.503,200],[0.502,1500],[0.501,100],[0.5,650],[0.25,60],[0.233,60],[0.232,572],[0.231,60],[0.23,60],[0.228,41.57],[0.227,25],[0.01,11908.49],[0.009,704.54],[0.008,50.4],[0.007,45.31],[0.006,40.24],[0.005,35.17],[0.004,30.12],[0.003,25.07],[0.002,20.04],[0.001,907.07]],"hash":"c4ec611dfa0ec22e5feb08654ccdaed1c096570b"}}
{"timestamp":1768863382803,"type":"book","data":{"type":"book","timestamp":1768863382803,"asset_id":"50983867355616416655423952313122695633917659698391114174631454013985844444839","market":"0xd5f9cc8238a4f20dd8ad877fb9d5ffa8e27c5d1cef0cb1ea0d40117e43b91221","bids":[],"asks":[[0.999,14.99],[0.99,50]],"hash":"62486496b03e6056a1fa341d5cd4682effec9b90"}}
{"timestamp":1768863382803,"type":"book","data":{"type":"book","timestamp":1768863382803,"asset_id":"104561417469280438624857704713303730213235315036975837304809065111097458149113","market":"0x74359b1889c9b4f5a84c1cac8cfd2dd6f48731fedb44f7a7e803b9c8cd6de6d8","bids":[],"asks":[[0.999,99999],[0.998,55000],[0.992,155],[0.991,56055],[0.99,27000],[0.989,155],[0.98,2100],[0.97,300],[0.95,200],[0.92,255],[0.903,100],[0.902,10700],[0.901,100],[0.9,3650],[0.86,50],[0.85,400],[0.849,662],[0.8,50],[0.73,50],[0.66,50],[0.53,100],[0.51,100],[0.503,200],[0.502,1500],[0.501,100],[0.5,650],[0.25,60],[0.233,60],[0.232,571],[0.231,60],[0.23,60],[0.176,26.33],[0.174,16.53],[0.173,25],[0.172,11.02],[0.01,2000],[0.009,704.54],[0.008,50.4],[0.007,45.31],[0.006,40.24],[0.005,35.17],[0.004,30.12],[0.003,25.07],[0.002,20.04],[0.001,5]],"hash":"0b33ea47c8466bbf7c33486315465abfd52c8fe5"}}
{"timestamp":1768863382803,"type":"book","data":{"type":"book","timestamp":1768863382803,"asset_id":"109974464011407510311184872783466711205513981066359875513765218021885225826488","market":"0xd832ad310ac0e7586c26de1784c8acb2d9e050ad9a264e2bea6db9c0dc0832ed","bids":[[0.001,99999],[0.002,55000],[0.008,155],[0.009,56055],[0.01,27050],[0.011,155],[0.02,1400],[0.05,1300],[0.08,155],[0.097,100],[0.098,10500],[0.099,100],[0.1,3600],[0.14,50],[0.141,1309],[0.47,100],[0.49,100],[0.497,200],[0.498,1500],[0.499,100],[0.5,650],[0.75,60],[0.767,60],[0.768,306],[0.769,60],[0.77,60],[0.771,5.51],[0.974,26.93],[0.975,25],[0.99,60],[0.991,704.54],[0.992,50.4],[0.993,45.31],[0.994,40.24],[0.995,35.17],[0.996,30.12],[0.997,25.07],[0.998,20.04],[0.999,5]],"asks":[],"hash":"4ccf5941579eb34db960ab4278f93f67e978c625"}}
{"timestamp":1768863382803,"type":"book","data":{"type":"book","timestamp":1768863382803,"asset_id":"24579524396187103736840535208642428472919490237386093648130273132471733218325","market":"0xc7def456adf8952db9672f973dcf89ca06106ec530bb462efb9b7c2fbb84ddbd","bids":[],"asks":[[0.999,99999],[0.998,55000],[0.992,155],[0.991,56055],[0.99,27095],[0.989,155],[0.98,2100],[0.97,300],[0.95,200],[0.92,255],[0.903,100],[0.902,10600],[0.901,100],[0.9,3500],[0.85,650],[0.84,15],[0.83,15],[0.8,50],[0.78,15],[0.77,30],[0.76,15],[0.73,15],[0.72,1829],[0.71,15],[0.69,15],[0.67,30],[0.66,65],[0.53,100],[0.51,100],[0.503,200],[0.502,1500],[0.501,100],[0.5,250],[0.43,400],[0.25,60],[0.233,60],[0.232,352],[0.231,60],[0.23,60],[0.229,25],[0.228,6.27],[0.01,2670],[0.009,20632.57]],"hash":"7a39cfd7a2c0bd5e9172d959256715f5c67f76f4"}}
{"timestamp":1768863382803,"type":"book","data":{"type":"book","timestamp":1768863382803,"asset_id":"57387565809979849367931485811783458230949362028360279464167270926827433389414","market":"0xd5f9cc8238a4f20dd8ad877fb9d5ffa8e27c5d1cef0cb1ea0d40117e43b91221","bids":[[0.001,14.99],[0.01,50]],"asks":[],"hash":"fffb9ab5b912865a2bc68618a278685f0270e5d6"}}
{"timestamp":1768863382803,"type":"book","data":{"type":"book","timestamp":1768863382803,"asset_id":"72300811647490128998831837378933981624665087909864960667694762257393293709099","market":"0xa011589aac6ecc279df805b5b5af8f624f16044eca2fdc89f4f554df3ea82fe5","bids":[],"asks":[[0.999,5000],[0.998,55000],[0.992,155],[0.99,27550],[0.989,155],[0.98,2100],[0.95,200],[0.92,255],[0.903,100],[0.901,100],[0.9,4000],[0.882,1397],[0.53,100],[0.51,100],[0.503,200],[0.501,100],[0.5,650],[0.25,159.99],[0.233,60],[0.231,60],[0.23,60],[0.229,25],[0.228,5.51],[0.01,95],[0.009,500]],"hash":"760c2756974090fdf215313e13ab80674ad76522"}}
{"timestamp":1768863382803,"type":"book","data":{"type":"book","timestamp":1768863382803,"asset_id":"80955465573788561519287799238070819726068512211014816914447962346674298193040","market":"0x8884313775cb4f37d3de3fa1e9afc797d9d0fb72cae523fbfa7853fab179d500","bids":[[0.001,99999],[0.002,55000],[0.008,155],[0.009,56055],[0.01,27000],[0.011,155],[0.02,1400],[0.05,1300],[0.08,155],[0.097,100],[0.098,10700],[0.099,100],[0.1,3650],[0.14,50],[0.15,400],[0.2,50],[0.27,50],[0.34,50],[0.47,100],[0.49,100],[0.497,200],[0.498,1500],[0.499,100],[0.5,650],[0.75,60],[0.767,60],[0.768,572],[0.769,60],[0.77,60],[0.772,41.57],[0.773,25],[0.99,11908.49],[0.991,704.54],[0.992,50.4],[0.993,45.31],[0.994,40.24],[0.995,35.17],[0.996,30.12],[0.997,25.07],[0.998,20.04],[0.999,907.07]],"asks":[],"hash":"174bcf7ce3dcc5ce68f0402141297cfa87720a8d"}}
{"timestamp":1768863382803,"type":"book","data":{"type":"book","timestamp":1768863382803,"asset_id":"97040212064446394960539836623423876178691598622568810188407885534471977571669","market":"0x4288c9795de3151e756e44062d7772b2767e5a6d213dea0a116d1317729a5e1a","bids":[],"asks":[[0.999,99999],[0.998,55000],[0.992,155],[0.991,56055],[0.99,27115.5],[0.989,155],[0.97,400],[0.95,1300],[0.92,155],[0.903,100],[0.902,10600],[0.901,100],[0.9,3500],[0.85,1312],[0.8,50],[0.73,50],[0.66,50],[0.53,100],[0.51,100],[0.503,200],[0.502,1500],[0.501,100],[0.5,650],[0.25,60],[0.233,60],[0.232,922],[0.231,60],[0.23,60],[0.229,25],[0.18,10.52],[0.07,6.19],[0.069,5.51],[0.01,60],[0.009,613.54],[0.008,50.4],[0.007,10045.31],[0.006,1372.24],[0.005,35.17],[0.004,30.12],[0.003,25.07],[0.002,20.04],[0.001,0.99]],"hash":"c9fd331679dba284f63d181b6651bfa9c3bf66ce"}}
{"timestamp":1768863382803,"type":"book","data":{"type":"book","timestamp":1768863382803,"asset_id":"8529817399593092932868619955036462122236499040969175261261611684243758201892","market":"0xab8df169971e779e7a5c7867fafa15340113bcebc1c2b6f4714c17f20b4c7868","bids":[[0.002,55000],[0.008,155],[0.01,27565],[0.011,155],[0.02,2100],[0.05,200],[0.08,255],[0.097,100],[0.099,100],[0.1,4000],[0.13,1313],[0.47,100],[0.49,100],[0.497,200],[0.499,100],[0.5,650],[0.75,60],[0.767,60],[0.769,60],[0.77,60],[0.779,50],[0.78,16.53],[0.99,35],[0.991,500]],"asks":[],"hash":"6c0bca6e120ee8638fcec988983bca758dfd38cf"}}
{"timestamp":1768863382803,"type":"book","data":{"type":"book","timestamp":1768863382803,"asset_id":"94160515795879566153002944972741512251146074743459279119403075652615644127934","market":"0x07d3174d7e1b4b22ad3109744e9768dc255e2fe8749cc25cfc8cc900b1d3c62e","bids":[],"asks":[[0.999,99999],[0.998,55000],[0.992,155],[0.991,56055],[0.99,27115.5],[0.989,155],[0.98,1100],[0.97,300],[0.95,200],[0.92,255],[0.903,100],[0.902,10600],[0.901,100],[0.9,3500],[0.859,1359],[0.8,50],[0.73,50],[0.66,50],[0.53,100],[0.51,100],[0.503,200],[0.502,1500],[0.501,100],[0.5,650],[0.25,60],[0.233,60],[0.232,572],[0.231,60],[0.23,60],[0.229,53],[0.228,25.64],[0.01,22.96],[0.009,1671.54],[0.008,50.4],[0.007,45.31],[0.006,40.24],[0.005,35.17],[0.004,35.63],[0.003,25.07],[0.002,20.04],[0.001,1362.18]],"hash":"c6f42c4a1014031c1d9bbce7b16184471a2bb9e8"}}
{"timestamp":1768863382803,"type":"book","data":{"type":"book","timestamp":1768863382803,"asset_id":"23982213020675018791507326977308149379200692959141537028293395142867568952427","market":"0x0afef6598f68b1b2d47bca956116bbaa7d11f39d665f883aae5cc126c8e991c9","bids":[[0.002,55000],[0.008,155],[0.01,27550],[0.011,155],[0.02,2100],[0.021,45],[0.024,15],[0.025,15],[0.026,15],[0.028,15],[0.05,200],[0.061,13.12],[0.08,255],[0.097,100],[0.099,100],[0.1,4000],[0.118,1397],[0.47,100],[0.49,100],[0.497,200],[0.499,100],[0.5,650],[0.75,60],[0.767,60],[0.769,60],[0.77,60],[0.99,51.88],[0.991,500],[0.992,30.51]],"asks":[],"hash":"89f0a5b69683d5ca3b44ceb91e08843ad47f2285"}}
{"timestamp":1768863382803,"type":"book","data":{"type":"book","timestamp":1768863382803,"asset_id":"105946555319717952586004333254949548955829524636247831439729957976174835757796","market":"0x29067ebc925c8bb2d14f0bb8c7946005e51538109dc2e4d201639a40232bc93c","bids":[[0.002,55000],[0.008,155],[0.01,27550],[0.011,155],[0.02,2100],[0.05,200],[0.08,255],[0.097,100],[0.099,100],[0.1,4000],[0.118,1397],[0.47,100],[0.49,100],[0.497,200],[0.499,100],[0.5,650],[0.75,60],[0.767,60],[0.769,60],[0.77,60],[0.99,95],[0.991,500],[0.992,30.51]],"asks":[],"hash":"86eb97cd57ab37ea9ba6420aa2926d0abeec78fb"}}
{"timestamp":1768863382803,"type":"book","data":{"type":"book","timestamp":1768863382803,"asset_id":"48880380018017890900431761786115484907392010962335433452913978045838402624310","market":"0x9f5498adae626b37f869b924cc5a599eda5a11da525059b1404f89f8713c51c6","bids":[],"asks":[[0.999,99999],[0.998,55000],[0.992,155],[0.991,56055],[0.99,27080.5],[0.989,155],[0.98,1100],[0.97,300],[0.95,200],[0.92,255],[0.903,100],[0.902,10800],[0.901,100],[0.9,3500],[0.85,400],[0.84,2079],[0.68,100],[0.53,100],[0.51,100],[0.503,200],[0.502,1500],[0.501,100],[0.5,650],[0.25,60],[0.233,60],[0.232,570],[0.231,60],[0.23,60],[0.229,79.99],[0.228,5.51],[0.01,60],[0.009,570]],"hash":"69fb43668078a9656c4f15feb330c3c2c303bdb0"}}
{"timestamp":1768863382804,"type":"book","data":{"type":"book","timestamp":1768863382804,"asset_id":"25956482380991640813348808462637848560995942866526952689992175052729937091125","market":"0x2397d58005858b5b7271c776adac1b4fa32491286339f3dc3139df9dece7d6c3","bids":[],"asks":[[0.999,99999],[0.998,55000],[0.992,155],[0.991,56055],[0.99,27085.5],[0.989,155],[0.98,405],[0.95,1300],[0.92,155],[0.903,100],[0.902,10600],[0.901,100],[0.9,3500],[0.85,650],[0.8,50],[0.73,3.68],[0.72,1554],[0.66,50],[0.53,100],[0.51,100],[0.503,200],[0.502,1500],[0.501,100],[0.5,650],[0.25,60],[0.233,60],[0.231,60],[0.23,60],[0.229,5.51],[0.01,25258.99],[0.009,12638]],"hash":"718315613e3b49cbb37c8ba3bf07a9403e032125"}}
{"timestamp":1768863382804,"type":"book","data":{"type":"book","timestamp":1768863382804,"asset_id":"58170043872476553471723118954807775331301830716581845479265936031297794924283","market":"0xc6dd49ce5ac996f24caedb7cf1a5325f10e2013df38d06118da35a7835f90d79","bids":[[0.001,99999],[0.002,55000],[0.008,155],[0.009,56055],[0.01,27090],[0.011,155],[0.02,11000],[0.03,11400],[0.05,200],[0.08,255],[0.097,100],[0.098,10800],[0.099,100],[0.1,3792],[0.15,1112],[0.2,287],[0.22,15],[0.23,50],[0.27,50],[0.28,1779],[0.3,287],[0.33,30],[0.34,50],[0.4,287],[0.47,100],[0.49,100],[0.497,200],[0.498,1500],[0.499,100],[0.5,650],[0.75,60],[0.76,13.11],[0.767,60],[0.768,351],[0.769,60],[0.77,184.36],[0.82,59.75],[0.9,72.51],[0.93,51.09],[0.931,25],[0.932,5.51],[0.99,3170.26],[0.991,30704.54],[0.992,50.4],[0.993,45.31],[0.994,40.24],[0.995,35.17],[0.996,30.12],[0.997,25.07],[0.998,20.04],[0.999,601.21]],"asks":[],"hash":"31fefd558f88bb05b6f96883100a0f063dd2cbf0"}}
{"timestamp":1768863382804,"type":"book","data":{"type":"book","timestamp":1768863382804,"asset_id":"85356151034142958812118326873548413742312509549787317293018964257573037506843","market":"0x2bf2d7f54a03b4b01cff5a9e010a7fa7c0532f40f111cc19050c4b7499794f87","bids":[[0.001,14.99],[0.01,100],[0.04,62],[0.05,30],[0.051,25],[0.18,7.54]],"asks":[],"hash":"7710db917e40767ab28fcc6d058801f55a762917"}}
{"timestamp":1768863382804,"type":"book","data":{"type":"book","timestamp":1768863382804,"asset_id":"73222854146421675752746898713600437350256675719760876211589957230651142068940","market":"0x1d9921b0a498d2f0f68351a35d4b5e5fd6b34f5800e2b0dc304fe82872fff15b","bids":[],"asks":[[0.999,104999],[0.998,55000],[0.992,155],[0.991,56055],[0.99,39824.96],[0.989,155],[0.98,13000],[0.97,11705],[0.96,350],[0.95,155],[0.94,1500],[0.93,1622],[0.92,155],[0.903,100],[0.902,10700],[0.901,100],[0.9,4905],[0.88,60],[0.85,400],[0.82,55],[0.8,1550],[0.75,68.96],[0.7,1300],[0.69,66],[0.64,6],[0.62,91.11],[0.61,12.67],[0.6,1307],[0.59,6],[0.57,100],[0.54,6],[0.53,115.21],[0.51,180.73],[0.503,200],[0.502,1500],[0.501,100],[0.5,404],[0.49,6],[0.48,300],[0.44,6],[0.4,31],[0.35,75],[0.32,398.84],[0.25,60],[0.24,10],[0.233,60],[0.231,60],[0.23,60],[0.2,70],[0.17,151],[0.12,25],[0.11,35.38],[0.07,14],[0.06,7650],[0.04,350],[0.01,4055.01],[0.009,704.54],[0.008,50.4],[0.007,45.31],[0.006,40.24],[0.005,35.17],[0.004,193.64],[0.003,25.07],[0.002,45.04],[0.001,1017006.32]],"hash":"a4d1fa10729da6827e3fe73b15f65307f1ef7902"}}
{"timestamp":1768863382804,"type":"book","data":{"type":"book","timestamp":1768863382804,"asset_id":"44593029081753584788926889114013513766238403243363877426124190880950967120544","market":"0xc6dd49ce5ac996f24caedb7cf1a5325f10e2013df38d06118da35a7835f90d79","bids":[],"asks":[[0.999,99999],[0.998,55000],[0.992,155],[0.991,56055],[0.99,27090],[0.989,155],[0.98,11000],[0.97,11400],[0.95,200],[0.92,255],[0.903,100],[0.902,10800],[0.901,100],[0.9,3792],[0.85,1112],[0.8,287],[0.78,15],[0.77,50],[0.73,50],[0.72,1779],[0.7,287],[0.67,30],[0.66,50],[0.6,287],[0.53,100],[0.51,100],[0.503,200],[0.502,1500],[0.501,100],[0.5,650],[0.25,60],[0.24,13.11],[0.233,60],[0.232,351],[0.231,60],[0.23,184.36],[0.18,59.75],[0.1,72.51],[0.07,51.09],[0.069,25],[0.068,5.51],[0.01,3170.26],[0.009,30704.54],[0.008,50.4],[0.007,45.31],[0.006,40.24],[0.005,35.17],[0.004,30.12],[0.003,25.07],[0.002,20.04],[0.001,601.21]],"hash":"5ee7319645b89046ad52b05c5d92f64ee2df5be5"}}
{"timestamp":1768863382804,"type":"book","data":{"type":"book","timestamp":1768863382804,"asset_id":"29048920123422896108922056005135610136327701403093628618323034011331962504239","market":"0x6964f9a8a358b91d5a0a13458445986bc803779225de647a0b9f0caff8f8aa04","bids":[[0.01,7050],[0.03,10832],[0.08,55],[0.1,500],[0.11,25],[0.12,5.51]],"asks":[],"hash":"d5b761cbb7501748c62f0298c61f06a35cedc20c"}}
{"timestamp":1768863382804,"type":"book","data":{"type":"book","timestamp":1768863382804,"asset_id":"32000187069377430896265944353073875929784130362721284251736314375740995009132","market":"0xa011589aac6ecc279df805b5b5af8f624f16044eca2fdc89f4f554df3ea82fe5","bids":[[0.001,5000],[0.002,55000],[0.008,155],[0.01,27550],[0.011,155],[0.02,2100],[0.05,200],[0.08,255],[0.097,100],[0.099,100],[0.1,4000],[0.118,1397],[0.47,100],[0.49,100],[0.497,200],[0.499,100],[0.5,650],[0.75,159.99],[0.767,60],[0.769,60],[0.77,60],[0.771,25],[0.772,5.51],[0.99,95],[0.991,500]],"asks":[],"hash":"2978968d04098477ad2eb58d4974a5f5f3dece78"}}
{"timestamp":1768863382804,"type":"book","data":{"type":"book","timestamp":1768863382804,"asset_id":"2281309566574130642807730816726303714419168586997236681707499099398936474185","market":"0x6dfb3d43cd0029526113cdd085d4ebab3fc9274d3095295d69ac24e27ab1dd98","bids":[],"asks":[[0.999,99999],[0.998,55000],[0.992,155],[0.991,56055],[0.99,27080.5],[0.989,155],[0.98,400],[0.95,1300],[0.92,155],[0.903,100],[0.902,10800],[0.901,100],[0.9,3500],[0.85,400],[0.84,2700],[0.53,100],[0.51,100],[0.503,200],[0.502,1500],[0.501,100],[0.5,650],[0.25,60],[0.233,60],[0.232,439],[0.231,60],[0.23,60],[0.229,100],[0.228,11.02],[0.02,300],[0.019,144],[0.009,497.91]],"hash":"8456816dba51ad6d4d16a11c2f58cf635095375d"}}
{"timestamp":1768863382804,"type":"book","data":{"type":"book","timestamp":1768863382804,"asset_id":"107120935694512385169050114827872789982020807731131881827825052191609346273122","market":"0x55bc05d0172e01f468ee39bf260c7fd132b4453c71a37d1834c5c7cce3db5a2e","bids":[],"asks":[[0.999,5000],[0.998,55000],[0.992,155],[0.99,27550],[0.989,155],[0.98,2100],[0.95,200],[0.92,255],[0.903,100],[0.901,100],[0.9,4000],[0.882,1397],[0.71,75.61],[0.53,100],[0.51,100],[0.503,200],[0.501,100],[0.5,650],[0.25,60],[0.233,60],[0.231,60],[0.23,60],[0.229,25],[0.009,500],[0.008,5.51]],"hash":"fe8dfbdfa98b357c0d25b55e43f98407b93be675"}}
{"timestamp":1768863382804,"type":"book","data":{"type":"book","timestamp":1768863382804,"asset_id":"93658466248405584999260870388818827582402881579193486826612628010719686456341","market":"0x0afef6598f68b1b2d47bca956116bbaa7d11f39d665f883aae5cc126c8e991c9","bids":[],"asks":[[0.998,55000],[0.992,155],[0.99,27550],[0.989,155],[0.98,2100],[0.979,45],[0.976,15],[0.975,15],[0.974,15],[0.972,15],[0.95,200],[0.939,13.12],[0.92,255],[0.903,100],[0.901,100],[0.9,4000],[0.882,1397],[0.53,100],[0.51,100],[0.503,200],[0.501,100],[0.5,650],[0.25,60],[0.233,60],[0.231,60],[0.23,60],[0.01,51.88],[0.009,500],[0.008,30.51]],"hash":"47c0938823b53e164d4066b913dd2553b3f7f229"}}
{"timestamp":1768863382804,"type":"book","data":{"type":"book","timestamp":1768863382804,"asset_id":"3986689974687749401569762749790970504891242225395088232355646709432459801755","market":"0x649872b98f3cd5c94d604030777b871d0ef6256d6c9485eef4dfd32c8e550870","bids":[],"asks":[[0.998,55000],[0.992,155],[0.99,27550],[0.989,155],[0.98,2100],[0.97,16],[0.96,25],[0.95,230],[0.92,255],[0.903,100],[0.901,100],[0.9,4100],[0.85,500],[0.53,100],[0.51,100],[0.503,200],[0.501,100],[0.5,650],[0.25,60],[0.233,60],[0.231,60],[0.23,60],[0.229,25],[0.228,5.51],[0.01,629.12],[0.009,500]],"hash":"002d089fc92068247890b74ebfb03383b072179a"}}
{"timestamp":1768863382804,"type":"book","data":{"type":"book","timestamp":1768863382804,"asset_id":"7360690154955731738072833984462694862220283551111167441524929099080928304759","market":"0x55bc05d0172e01f468ee39bf260c7fd132b4453c71a37d1834c5c7cce3db5a2e","bids":[[0.001,5000],[0.002,55000],[0.008,155],[0.01,27550],[0.011,155],[0.02,2100],[0.05,200],[0.08,255],[0.097,100],[0.099,100],[0.1,4000],[0.118,1397],[0.29,75.61],[0.47,100],[0.49,100],[0.497,200],[0.499,100],[0.5,650],[0.75,60],[0.767,60],[0.769,60],[0.77,60],[0.771,25],[0.991,500],[0.992,5.51]],"asks":[],"hash":"dc3b68fffd68505dd79dce1f3b467c45325aeee1"}}
{"timestamp":1768863382805,"type":"book","data":{"type":"book","timestamp":1768863382805,"asset_id":"106502645861422820101428418410740039040950178042688282565606126950746542596804","market":"0x19d9dc9b734a8270440da3511c0127c64e18e7c034656dba600c67e1f671eec8","bids":[],"asks":[[0.998,55000],[0.992,155],[0.99,27550],[0.989,155],[0.98,2100],[0.95,200],[0.92,255],[0.903,100],[0.901,100],[0.9,4000],[0.859,1259],[0.53,100],[0.51,100],[0.503,200],[0.501,100],[0.5,250],[0.45,427.36],[0.25,60],[0.233,60],[0.231,60],[0.23,60],[0.229,25],[0.228,5.51],[0.01,69.49],[0.009,500]],"hash":"9441c96c2bbb46ae44a9d3b25e9e0eaeb864706d"}}
{"timestamp":1768863382805,"type":"book","data":{"type":"book","timestamp":1768863382805,"asset_id":"34130029555333481410138913504371238679856860292518927586466769475661539617443","market":"0xe0c45c38597364a10040b4cd5b6b68e099fa0f67a7cf906b7fda8acbc981b382","bids":[],"asks":[[0.998,55000],[0.992,155],[0.99,27550],[0.989,155],[0.98,2100],[0.95,200],[0.92,255],[0.903,100],[0.901,100],[0.9,4000],[0.87,1313],[0.53,100],[0.51,100],[0.503,200],[0.501,100],[0.5,650],[0.25,60],[0.233,60],[0.231,60],[0.23,60],[0.229,25],[0.228,5.51],[0.01,35],[0.009,500]],"hash":"722c1f5b361df1f1fa7f95d66424cce978c937f7"}}
{"timestamp":1768863382805,"type":"book","data":{"type":"book","timestamp":1768863382805,"asset_id":"49335016365941641409952976129113215306810130872796911770220968674695550227620","market":"0xa8e21d98ce3635fdafa916aa404f8dfd4eb941ec5a36e54b07f9fef1dcfa9051","bids":[[0.001,14.99],[0.01,50],[0.95,20],[0.979,24.36],[0.98,25],[0.981,5.51]],"asks":[],"hash":"095ce2246e6ed6c2906f07a768dd914d4bedd740"}}
{"timestamp":1768863382805,"type":"book","data":{"type":"book","timestamp":1768863382805,"asset_id":"5689681855689828399428106754866979922401730116817121622527657120513897525909","market":"0x994852b813326db703afc598ac97f4baec56a0e9da0e586d9a0154f8b146df28","bids":[[0.01,7050],[0.02,5000],[0.08,55],[0.1,500],[0.11,2954],[0.24,30.29],[0.28,37.5],[0.29,25]],"asks":[],"hash":"3495e7869d5062a0697a13978b79e67287dca620"}}
{"timestamp":1768863382805,"type":"book","data":{"type":"book","timestamp":1768863382805,"asset_id":"60854482386705306074271452945147814262686505626338572994501795906620218532455","market":"0xd832ad310ac0e7586c26de1784c8acb2d9e050ad9a264e2bea6db9c0dc0832ed","bids":[],"asks":[[0.999,99999],[0.998,55000],[0.992,155],[0.991,56055],[0.99,27050],[0.989,155],[0.98,1400],[0.95,1300],[0.92,155],[0.903,100],[0.902,10500],[0.901,100],[0.9,3600],[0.86,50],[0.859,1309],[0.53,100],[0.51,100],[0.503,200],[0.502,1500],[0.501,100],[0.5,650],[0.25,60],[0.233,60],[0.232,306],[0.231,60],[0.23,60],[0.229,5.51],[0.026,26.93],[0.025,25],[0.01,60],[0.009,704.54],[0.008,50.4],[0.007,45.31],[0.006,40.24],[0.005,35.17],[0.004,30.12],[0.003,25.07],[0.002,20.04],[0.001,5]],"hash":"6bb709dac3dc8a0bc6cfb5f71bed9ce709b9b63e"}}
{"timestamp":1768863382805,"type":"book","data":{"type":"book","timestamp":1768863382805,"asset_id":"24149837465812544749905902967180296948686555674306251030277465520781639999133","market":"0xa080927f19a54d86c89bd3555541b3abfbf53e98cf0e5f964e1729528e7df2d6","bids":[],"asks":[[0.99,150]],"hash":"7e9b4e3b0d06ae1587ae7401782d232867828d1f"}}
{"timestamp":1768863382805,"type":"book","data":{"type":"book","timestamp":1768863382805,"asset_id":"23288743695636620381867808278031544648048214106114607887269598951056044003098","market":"0xc3bb03827ffd54c915712e01268060664edc4b9a7e10c3687a46414a8fbd61fa","bids":[],"asks":[[0.998,55000],[0.992,155],[0.99,27550],[0.989,155],[0.98,2100],[0.95,200],[0.92,255],[0.903,100],[0.901,100],[0.9,4000],[0.882,1397],[0.53,100],[0.525,75.62],[0.51,100],[0.503,200],[0.501,100],[0.5,650],[0.25,60],[0.233,60],[0.231,60],[0.23,60],[0.229,25],[0.01,95],[0.009,500],[0.008,10.51]],"hash":"35ae243e454bed9336e11b4c23d0f1667bd5e71f"}}
